Workbook

Sheet Energy input per carrier
A1: Energy Carrier | B1: Sector | C1: 2025 | D1: 2030 | E1: 2035 | F1: 2040 | G1: 2045 | H1: 2050
A2: Aardgas | B2: Basic metal non-ferro | C2: 0.57206719 | D2: 0.70591185 | E2: 0.62987196 | F2: 0.70269747 | G2: 0.31582183 | H2: 0.33739368
A3: Aardgas | B3: Basismetaal ferro | C3: 0.00035888613 | D3: 21.091734 | E3: 32.333775 | F3: 32.09502 | G3: 25.791173 | H3: 23.144778
A4: Aardgas | B4: Chemie | C4: 45.035615 | D4: 33.964527 | E4: 26.77583 | F4: 19.115965 | G4: 10.645055 | H4: 9.1783343
A5: Aardgas | B5: Elektriciteitsopwekking | C5: 330 | D5: 164.54303 | E5: 96.549437 | F5: 66.209741 | G5: 67.686415 | H5: 70.298685
A6: Aardgas | B6: Food and Beverage Industry | C6: 62.511431 | D6: 19.648805 | E6: 7.1722837 | F6: 5.4032304 | G6: 3.6507081 | H6: 20.225698
A7: Aardgas | B7: Gasvoorziening | C7: 9.1950553e-05 | D7: 0.00043894167 | E7: 0.00015776873 | F7: 2.5047041e-06 | G7: 5.2192039e-05 | H7: 0.00020681583
A8: Aardgas | B8: H2 voorziening | C8: 73.120232 | D8: 81.626755 | E8: 78.453321 | F8: 77.877015 | G8: 36.566929 | H8: 21.794158
A9: Aardgas | B9: HDO | C9: 65.391536 | D9: 68.360117 | E9: 65.719682 | F9: 52.988326 | G9: 64.03542 | H9: 55.676491
A10: Aardgas | B10: Huishoudens | C10: 252.41008 | D10: 233.94287 | E10: 224.80057 | F10: 198.90223 | G10: 177.59711 | H10: 156.19134
A11: Aardgas | B11: Industrie | C11: 39.71117 | D11: 45.782639 | E11: 35.642607 | F11: 28.438242 | G11: 24.055304 | H11: 23.787915
A12: Aardgas | B12: Kunstmestindustrie | C12: 79.046047 | D12: 66.650256 | E12: 59.829772 | F12: 53.400889 | G12: 45.793112 | H12: 38.155236
A13: Aardgas | B13: Landbouw | C13: 82.317621 | D13: 58.642398 | E13: 20.002627 | F13: 18.550036 | G13: 12.264384 | H13: 1.940122
... A31: Bio-DME | B31: Verkeer | C31: 2.9288998e-05 | D31: 0.1000247 | E31: 0.10002825 | F31: 0.10000038 | G31: 0.10000805 | H31: 0.10000874
A32: Bio-LNG for shipping | B32: 0 | C32: 0.049371467 | D32: 0 | E32: 0 | F32: 0 | G32: 0 | H32: 0
A33: Bio-LNG for shipping | B33: Bunkers | C33: 0.15062778 | D33: 0.0057538832 | E33: 4.2694057e-05 | F33: 5.6628217 | G33: 10.527763 | H33: 10.126468
A34: Bio-LPG | B34: MWT | C34: 0.033794713 | D34: 0.027403261 | E34: 0.025939218 | F34: 0.042093146 | G34: 0.029375806 | H34: 0.031381226
A35: Bio-LPG | B35: Verkeer | C35: 0.066206197 | D35: 0.072673022 | E35: 0.074103237 | F35: 0.057907274 | G35: 0.084352298 | H35: 0.078522955
A36: Bio-Methanol for shipping | B36: Bunkers | C36: 0 | D36: 0.00012950917 | E36: 5.9659158e-05 | F36: 0.10000118 | G36: 0.10004148 | H36: 0.1001556
A37: Bio-aromatics | B37: Chemie | C37: 1.157251 | D37: 0.61674104 | E37: 0.4876356 | F37: 1.1261385 | G37: 1.5829509 | H37: 2.4003631
A38: Bio-ethanol | B38: Biofuel | C38: 0 | D38: 1.1036651e-05 | E38: 2.9101907e-05 | F38: 6.9234882e-07 | G38: 4.7911747e-05 | H38: 5.8714355e-05
A39: Bio-ethanol | B39: Chemie | C39: 3.6196604e-07 | D39: 0 | E39: 0 | F39: 0 | G39: 0 | H39: 0
A40: Bio-ethanol | B40: MWT | C40: 0 | D40: 0.12631769 | E40: 0.075651207 | F40: 0.022252872 | G40: 0.032026486 | H40: 0.027127321
A41: Bio-ethanol | B41: Verkeer | C41: 12.000001 | D41: 10.859193 | E41: 8.449502 | F41: 0.6511096 | G41: 0.61992596 | H41: 0.10332111
A42: Bio-restgassen | B42: Basismetaal ferro | C42: 0.31663156 | D42: 0.00016480623 | E42: 0.0014742095 | F42: 0.0020445677 | G42: 2.247977e-05 | H42: 0.0067829222
A43: Bio-restgassen | B43: Chemie | C43: 1.6190947 | D43: 0.51124663 | E43: 0.40544082 | F43: 0.33671646 | G43: 0.27573416 | H43: 3.0838394
A44: Bio-restgassen | B44: H2 voorziening | C44: 2.0200452e-06 | D44: 2.5213477e-05 | E44: 3.8773299e-06 | F44: 0 | G44: 0 | H44: 6.513677e-06
... A46: Bio-restgassen | B46: Raffinaderijen | C46: 0.85560327 | D46: 0.26344105 | E46: 0.2107893 | F46: 0.15708728 | G46: 0.11696014 | H46: 0.87385496
A47: BioHFO | B47: 0 | C47: 4.1635661e-06 | D47: 0 | E47: 0 | F47: 0 | G47: 0 | H47: 0
A48: BioHFO | B48: Bunkers | C48: 4.2014401e-06 | D48: 0.1000212 | E48: 0.10000295 | F48: 0.099999991 | G48: 0.099999804 | H48: 0.10000622
A49: Biobenzine | B49: MWT | C49: 0.13780665 | D49: 0.016900775 | E49: 0.014081333 | F49: 0.023652009 | G49: 1.1698508e-05 | H49: 0.03554392
A50: Biobenzine | B50: Verkeer | C50: 1.5662413 | D50: 0.083321441 | E50: 0.086118217 | F50: 0.076350824 | G50: 0.2168626 | H50: 0.14868122
A51: Biodiesel | B51: Bunkers | C51: 0 | D51: 20.573599 | E51: 16.436813 | F51: 2.5057571e-05 | G51: 20.402401 | H51: 0.0015941542
A52: Biodiesel | B52: MWT | C52: 10.389364 | D52: 0.00033721586 | E52: 0.00072199087 | F52: 6.4409515 | G52: 0.00047110511 | H52: 6.5904768
A53: Biodiesel | B53: Verkeer | C53: 33.610694 | D53: 0.1082484 | E53: 0.001649346 | F53: 11.720085 | G53: 0.0010613887 | H53: 12.948362
A54: Biodiesel | B54: Waste | C54: 0 | D54: 0.0001062613 | E54: 0.00019615389 | F54: 0.05806788 | G54: 0.00021860681 | H54: 0.031865891
A55: Biogas | B55: Biofuel | C55: 5.4446785e-06 | D55: 0.0002720383 | E55: 0.00017430491 | F55: 2.2589123e-06 | G55: 0.00016598663 | H55: 0.0017651561
A56: Biogas | B56: Gasvoorziening | C56: 4.4115488 | D56: 0.00080600068 | E56: 0.00020025517 | F56: 5.5628368 | G56: 10.4278 | H56: 10.026671
A57: Biogas | B57: HDO | C57: 0 | D57: 0.00084485093 | E57: 0.00027043929 | F57: 0.0004569017 | G57: 3.0959439 | H57: 2.058743
A58: Biogas | B58: Huishoudens | C58: 0 | D58: 0.00019531542 | E58: 7.0579573e-05 | F58: 0.00036566069 | G58: 2.4116025 | H58: 1.776896
...

Sheet IND
A1: Variable | B1: Sector | C1: Unit | E1: 2025 | F1: 2030 | G1: 2035 | H1: 2040 | I1: 2045 | J1: 2050
A2: Investments | B2: AGR01 | C2: th_euro | E2: 0 | F2: 0 | G2: 0 | H2: 0 | I2: 0 | J2: 0
A3: Investments | B3: AGR01 | C3: th_euro | D3: PGT09 | E3: 0 | F3: 0 | G3: 0 | H3: 0 | I3: 0 | J3: 0
A4: Energy Use | B4: AGR01 | C4: TJ | D4: ENE01 | E4: 0 | F4: 0 | G4: 0 | H4: 0 | I4: 0 | J4: 0
A5: Energy Use | B5: AGR01 | C5: TJ | D5: ENE02 | E5: 0 | F5: 0 | G5: 0 | H5: 0 | I5: 0 | J5: 0
A6: Energy Use | B6: AGR01 | C6: TJ | D6: ENE03 | E6: ='Energy input per carrier'!C183*1000 -> 11565.271 | F6: ='Energy input per carrier'!D183*1000 -> 0.040648532 | G6: ='Energy input per carrier'!E183*1000 -> 0.054424899 | H6: ='Energy input per carrier'!F183*1000 -> 0.00061527495 | I6: ='Energy input per carrier'!G183*1000 -> 0.013188794 | J6: ='Energy input per carrier'!H183*1000 -> 0.093390029
A7: Energy Use | B7: AGR01 | C7: TJ | D7: ENE04 | E7: ='Energy input per carrier'!C13*1000 -> 82317.621 | F7: ='Energy input per carrier'!D13*1000 -> 58642.398 | G7: ='Energy input per carrier'!E13*1000 -> 20002.627 | H7: ='Energy input per carrier'!F13*1000 -> 18550.036 | I7: ='Energy input per carrier'!G13*1000 -> 12264.384 | J7: ='Energy input per carrier'!H13*1000 -> 1940.122
A8: Energy Use | B8: AGR01 | C8: TJ | D8: ENE05 | E8: ='Energy input per carrier'!C130*1000 -> 31671.711 | F8: ='Energy input per carrier'!D130*1000 -> 47417.85 | G8: ='Energy input per carrier'!E130*1000 -> 50365.948 | H8: ='Energy input per carrier'!F130*1000 -> 54506.219 | I8: ='Energy input per carrier'!G130*1000 -> 56107.92 | J8: ='Energy input per carrier'!H130*1000 -> 58075.784
A9: Energy Use | B9: AGR01 | C9: TJ | D9: ENE06 | E9: =('Tech, Carrier & Sector by Year'!D172+'Tech, Carrier & Sector by Year'!D1391+'Tech, Carrier & Sector by Year'!D802+'Tech, Carrier & Sector by Year'!D2069)*1000 -> 15400 | F9: =('Tech, Carrier & Sector by Year'!E172+'Tech, Carrier & Sector by Year'!E1391+'Tech, Carrier & Sector by Year'!E802+'Tech, Carrier & Sector by Year'!E2069)*1000 -> 8800.0557 | G9: =('Tech, Carrier & Sector by Year'!F172+'Tech, Carrier & Sector by Year'!F1391+'Tech, Carrier & Sector by Year'!F802+'Tech, Carrier & Sector by Year'!F2069)*1000 -> 15000 | H9: =('Tech, Carrier & Sector by Year'!G172+'Tech, Carrier & Sector by Year'!G1391+'Tech, Carrier & Sector by Year'!G802+'Tech, Carrier & Sector by Year'!G2069)*1000 -> 15000 | I9: =('Tech, Carrier & Sector by Year'!H172+'Tech, Carrier & Sector by Year'!H1391+'Tech, Carrier & Sector by Year'!H802+'Tech, Carrier & Sector by Year'!H2069)*1000 -> 15000 | J9: =('Tech, Carrier & Sector by Year'!I172+'Tech, Carrier & Sector by Year'!I1391+'Tech, Carrier & Sector by Year'!I802+'Tech, Carrier & Sector by Year'!I2069)*1000 -> 15000.001
A10: Energy Use | B10: AGR01 | C10: TJ | D10: ENE07 | E10: 0 | F10: 0 | G10: 0 | H10: 0 | I10: 0 | J10: 0
A11: Energy Use | B11: AGR01 | C11: TJ | D11: ENE08 | E11: 0 | F11: 0 | G11: 0 | H11: 0 | I11: 0 | J11: 0
A12: Energy Use | B12: AGR01 | C12: TJ | D12: ENE09 | E12: 0 | F12: 0 | G12: 0 | H12: 0 | I12: 0 | J12: 0
A13: Energy Use | B13: AGR01 | C13: TJ | D13: ENE10 | E13: 0 | F13: 0 | G13: 0 | H13: 0 | I13: 0 | J13: 0
A14: Energy Use | B14: AGR01 | C14: TJ | D14: ENE11 | E14: 0 | F14: 0 | G14: 0 | H14: 0 | I14: 0 | J14: 0
A15: Residential
A16: Variable | B16: Sector | C16: Unit | E16: 0 | F16: 0 | G16: 0 | H16: 0 | I16: 0 | J16: 0
A17: Investments | B17: Equipments | C17: th_euro | E17: 0 | F17: 0 | G17: 0 | H17: 0 | I17: 0 | J17: 0
A18: Investments | B18: PV | C18: th_euro | E18: 0 | F18: 0 | G18: 0 | H18: 0 | I18: 0 | J18: 0
A19: Energy Use | B19: Equipments | C19: TJ | D19: ENE01 | E19: 0 | F19: 0 | G19: 0 | H19: 0 | I19: 0 | J19: 0
A20: Energy Use | B20: Equipments | C20: TJ | D20: ENE02 | E20: ='Energy input per carrier'!C191*1000 -> 1465.0197 | F20: ='Energy input per carrier'!D191*1000 -> 967.71765 | G20: ='Energy input per carrier'!E191*1000 -> 869.80192 | H20: ='Energy input per carrier'!F191*1000 -> 803.23731 | I20: ='Energy input per carrier'!G191*1000 -> 788.7671 | J20: ='Energy input per carrier'!H191*1000 -> 771.8378
A21: Energy Use | B21: Equipments | C21: TJ | D21: ENE03
A22: Energy Use | B22: Equipments | C22: TJ | D22: ENE04 | E22: ='Energy input per carrier'!C10*1000 -> 252410.08 | F22: ='Energy input per carrier'!D10*1000 -> 233942.87 | G22: ='Energy input per carrier'!E10*1000 -> 224800.57 | H22: ='Energy input per carrier'!F10*1000 -> 198902.23 | I22: ='Energy input per carrier'!G10*1000 -> 177597.11 | J22: ='Energy input per carrier'!H10*1000 -> 156191.34
A23: Energy Use | B23: Equipments | C23: TJ | D23: ENE05 | E23: =('Energy input per carrier'!C127)*1000 -> 78180.583 | F23: =('Energy input per carrier'!D127)*1000 -> 79385.044 | G23: =('Energy input per carrier'!E127)*1000 -> 85360.6 | H23: =('Energy input per carrier'!F127)*1000 -> 89907.802 | I23: =('Energy input per carrier'!G127)*1000 -> 92458.327 | J23: =('Energy input per carrier'!H127)*1000 -> 101444.55
A24: Energy Use | B24: Equipments | C24: TJ | D24: ENE06 | E24: ='Energy input per carrier'!C80*1000 -> 16000 | F24: ='Energy input per carrier'!D80*1000 -> 11844.511 | G24: ='Energy input per carrier'!E80*1000 -> 11305.711 | H24: ='Energy input per carrier'!F80*1000 -> 11306.96 | I24: ='Energy input per carrier'!G80*1000 -> 11311.852 | J24: ='Energy input per carrier'!H80*1000 -> 11304.311
A25: Energy Use | B25: Equipments | C25: TJ | D25: ENE07 | E25: ='Energy input per carrier'!C58*1000 -> 0 | F25: ='Energy input per carrier'!D58*1000 -> 0.19531542 | G25: ='Energy input per carrier'!E58*1000 -> 0.070579573 | H25: ='Energy input per carrier'!F58*1000 -> 0.36566069 | I25: ='Energy input per carrier'!G58*1000 -> 2411.6025 | J25: ='Energy input per carrier'!H58*1000 -> 1776.896
A26: Energy Use | B26: Equipments | C26: TJ | D26: ENE08 | E26: 0 | F26: 0 | G26: 0 | H26: 0 | I26: 0 | J26: 0
A27: Energy Use | B27: Equipments | C27: TJ | D27: ENE09 | E27: ='Energy input per carrier'!C276*1000 -> 0.014134539 | F27: ='Energy input per carrier'!D276*1000 -> 9.2463735 | G27: ='Energy input per carrier'!E276*1000 -> 3.1531099 | H27: ='Energy input per carrier'!F276*1000 -> 4.10524 | I27: ='Energy input per carrier'!G276*1000 -> 4.5379248 | J27: ='Energy input per carrier'!H276*1000 -> 3.4472717
A28: Energy Use | B28: Equipments | C28: TJ | D28: ENE10 | E28: 0 | F28: 0 | G28: 0 | H28: 0 | I28: 0 | J28: 0
A29: Energy Use | B29: Equipments | C29: TJ | D29: ENE11 | G29: 0 | H29: 0 | I29: 0 | J29: 0
A34: Variable | B34: Sector | C34: Unit | E34: 2025 | F34: 2030 | G34: 2035 | H34: 2040 | I34: 2045 | J34: 2050
A35: Energy Use | B35: IND01 | C35: TJ | D35: ENE01 | E35: ='Energy input per carrier'!C176*1000 -> 119126.39 | F35: =('Energy input per carrier'!F176)*1000 -> 40373.869 | G35: =('Energy input per carrier'!G176)*1000 -> 47488.936 | H35: =('Energy input per carrier'!H176)*1000 -> 52287.472 | I35: =('Energy input per carrier'!I176)*1000 -> 0 | J35: =('Energy input per carrier'!J176)*1000 -> 0
A36: Energy Use | B36: IND01 | C36: TJ | D36: ENE02 | E36: 0 | F36: 0 | G36: 0 | H36: 0 | I36: 0 | J36: 0
A37: Energy Use | B37: IND01 | C37: TJ | D37: ENE03 | E37: ='Energy input per carrier'!C108*1000 -> 201.59999 | F37: ='Energy input per carrier'!D108*1000 -> 111.46693 | G37: ='Energy input per carrier'!E108*1000 -> 75.880047 | H37: ='Energy input per carrier'!F108*1000 -> 68.320003 | I37: ='Energy input per carrier'!G108*1000 -> 80.360005 | J37: ='Energy input per carrier'!H108*1000 -> 88.480087
A38: Energy Use | B38: IND01 | C38: TJ | D38: ENE04 | E38: ='Energy input per carrier'!C3*1000 -> 0.35888613 | F38: ='Energy input per carrier'!D3*1000 -> 21091.734 | G38: ='Energy input per carrier'!E3*1000 -> 32333.775 | H38: ='Energy input per carrier'!F3*1000 -> 32095.02 | I38: ='Energy input per carrier'!G3*1000 -> 25791.173 | J38: ='Energy input per carrier'!H3*1000 -> 23144.778
A39: Energy Use | B39: IND01 | C39: TJ | D39: ENE05 | E39: ='Energy input per carrier'!C118*1000 -> 10230.569 | F39: ='Energy input per carrier'!D118*1000 -> 10235.432 | G39: ='Energy input per carrier'!E118*1000 -> 11607.619 | H39: ='Energy input per carrier'!F118*1000 -> 11302.933 | I39: ='Energy input per carrier'!G118*1000 -> 10232.742 | J39: ='Energy input per carrier'!H118*1000 -> 11541.048
A40: Energy Use | B40: IND01 | C40: TJ | D40: ENE06 | E40: ='Energy input per carrier'!C72*1000 -> 6083.709 | F40: ='Energy input per carrier'!D72*1000 -> 5835.3846 | G40: ='Energy input per carrier'!E72*1000 -> 5612.828 | H40: ='Energy input per carrier'!F72*1000 -> 5711.8852 | I40: ='Energy input per carrier'!G72*1000 -> 5122.1785 | J40: ='Energy input per carrier'!H72*1000 -> 0.55305883
A41: Energy Use | B41: IND01 | C41: TJ | D41: ENE07 | E41: 0 | F41: 0 | G41: 0 | H41: 0 | I41: 0 | J41: 0
A42: Energy Use | B42: IND01 | C42: TJ | D42: ENE08 | E42: 0 | F42: 0 | G42: 0 | H42: 0 | I42: 0 | J42: 0
A43: Energy Use | B43: IND01 | C43: TJ | D43: ENE09 | E43: ='Energy input per carrier'!C267*1000 -> 0.0052049362 | F43: ='Energy input per carrier'!D267*1000 -> 0.046505883 | G43: ='Energy input per carrier'!E267*1000 -> 0.037830235 | H43: ='Energy input per carrier'!F267*1000 -> 0.00045929608 | I43: ='Energy input per carrier'!G267*1000 -> 0.014923998 | J43: ='Energy input per carrier'!H267*1000 -> 0.059964303
A44: Energy Use | B44: IND01 | C44: TJ | D44: ENE10 | E44: 0 | F44: 0 | G44: 0 | H44: 0 | I44: 0 | J44: 0
...

Sheet Tech, Carrier & Sector by Year
A1: Technology | B1: Energy Carrier | C1: Sector | D1: 2025 | E1: 2030 | F1: 2035 | G1: 2040 | H1: 2045 | I1: 2050
A2: 1003 Micro-WKK Brandstofcel 2011 (WB nieuwbouw) | B2: Elektriciteit | C2: Huishoudens | D2: 0 | E2: -2.8483875e-07 | F2: -2.0253418e-07 | G2: 0 | H2: -3.9194613e-07 | I2: -3.947984e-07
A3: 1003 Micro-WKK Brandstofcel 2011 (WB nieuwbouw) | B3: Warmte | C3: Huishoudens | D3: 0 | E3: -3.0061007e-07 | F3: -3.024147e-07 | G3: 0 | H3: -6.3685735e-07 | I3: -5.9235012e-07
A4: 1003 Micro-WKK Brandstofcel 2011 (WB nieuwbouw) | B4: Waterstof | C4: Huishoudens | D4: 0 | E4: 3.2970598e-07 | F4: 4.8668062e-07 | G4: 0 | H4: 1.0886851e-06 | I4: 9.5680607e-07
A5: 1010 Micro-WKK Brandstofcel 2011 (WB bestaande bouw) | B5: Elektriciteit | C5: Huishoudens | D5: 0 | E5: 0 | F5: 0 | G5: 0 | H5: 0 | I5: 0
A6: 1010 Micro-WKK Brandstofcel 2011 (WB bestaande bouw) | B6: Warmte | C6: Huishoudens | D6: 0 | E6: 0 | F6: 0 | G6: 0 | H6: 0 | I6: 0
A7: 1010 Micro-WKK Brandstofcel 2011 (WB bestaande bouw) | B7: Waterstof | C7: Huishoudens | D7: 0 | E7: 0 | F7: 0 | G7: 0 | H7: 0 | I7: 0
A8: 1012 Solar-PV Residential | B8: Elektriciteit | C8: Huishoudens | D8: -37.080362 | E8: -29.859767 | F8: -30.326279 | G8: -47.025141 | H8: -31.259398 | I8: -48.450141
A9: 1012 Solar-PV Residential | B9: Zon | C9: Huishoudens | D9: 37.080362 | E9: 29.859767 | F9: 30.326279 | G9: 47.025141 | H9: 31.259398 | I9: 48.450141 | L9: Hydrogen | M9: Unit | N9: code | O9: 2025 | P9: 2030 | Q9: 2035 | R9: 2040 | S9: 2045 | T9: 2050
A10: 1013 Biomassavergassing met CCS 7000u 2011 | B10: Biomassa (hout) | C10: Elektriciteitsopwekking | E10: 5.3979266e-05 | F10: 2.0531186e-05 | G10: 2.0793194e-07 | H10: 4.6149542e-06 | I10: 1.4450623e-05 | J10: Wind onshore | K10: Hyd | L10: Blue | M10: TJ | N10: BH | O10: =($D$16+$D$49+$D$669+$D$1030+D1034+D1038+D1046+D1858+D1974)*-1000 -> 54163.087 | P10: =(E16+E49+E669+E1030+E1034+E1038+E1046+E1858+E1974)*-1000 -> 60006.615 | Q10: =(F16+F49+F669+F1030+F1034+F1038+F1046+F1858+F1974)*-1000 -> 58965.858 | R10: =(G16+G49+G669+G1030+G1034+G1038+G1046+G1858+G1974)*-1000 -> 59768.269 | S10: =(H16+H49+H669+H1030+H1034+H1038+H1046+H1858+H1974)*-1000 -> 28526.564 | T10: =(I16+I49+I669+I1030+I1034+I1038+I1046+I1858+I1974)*-1000 -> 17527.386
A11: 1013 Biomassavergassing met CCS 7000u 2011 | B11: CO2Flow | C11: Elektriciteitsopwekking | E11: -5.3245195e-06 | F11: -2.025198e-06 | G11: 0 | H11: -4.5521948e-07 | I11: -1.4254107e-06 | J11: Gas fired | K11: Hyd | L11: Green | M11: TJ | N11: GH | O11: =(D1356+D1358+D1360+D1377)*-1000 -> 0 | P11: =(E1356+E1358+E1360+E1377)*-1000 -> 0.092496429 | Q11: =(F1356+F1358+F1360+F1377)*-1000 -> 0.08884642 | R11: =(G1356+G1358+G1360+G1377)*-1000 -> 0.0016307926 | S11: =(H1356+H1358+H1360+H1377)*-1000 -> 28373.363 | T11: =(I1356+I1358+I1360+I1377)*-1000 -> 38458.969
A12: 1013 Biomassavergassing met CCS 7000u 2011 | B12: Elektriciteit | C12: Elektriciteitsopwekking | E12: -3.6521321e-07 | F12: -1.2125396e-06 | G12: 0 | H12: -1.8916248e-06 | I12: -3.7118601e-06 | J12: Gas fired | K12: Hyd | L12: Total | M12: TJ | N12: T | O12: =O10+O11 -> 54163.087 | P12: =P10+P11 -> 60006.708 | Q12: =Q10+Q11 -> 58965.947 | R12: =R10+R11 -> 59768.27 | S12: =S10+S11 -> 56899.927 | T12: =T10+T11 -> 55986.355
A13: 1016 ATR with CC | B13: Aardgas | C13: H2 voorziening | D13: 0 | E13: 0.0003967363 | F13: 13.154776 | G13: 25.639268 | H13: 16.749879 | I13: 15.33429 | J13: Solar PV - Services
A14: 1016 ATR with CC | B14: CO2Flow | C14: H2 voorziening | D14: 0 | E14: -2.104074e-05 | F14: -0.68499555 | G14: -1.335088 | H14: -0.87219967 | I14: -0.79848725 | J14: Solar PV - Agriculture
A15: 1016 ATR with CC | B15: Elektriciteit | C15: H2 voorziening | D15: 0 | E15: 1.6779467e-05 | F15: 0.54811571 | G15: 1.0683028 | H15: 0.6979116 | I15: 0.63892884 | J15: Solar PV - Services
A16: 1016 ATR with CC | B16: Waterstof | C16: H2 voorziening | D16: 0 | E16: -0.00033672511 | F16: -10.962314 | G16: -21.366057 | H16: -13.958232 | I16: -12.778577 | J16: Solar PV - Electricity sector
A17: 1017 Kolenvergassing CCS 7000u eDesign 2011 | B17: CO2Flow | C17: Elektriciteitsopwekking | E17: 0 | F17: 0 | G17: 0 | H17: 0 | I17: 0 | J17: Gas fired
A18: 1017 Kolenvergassing CCS 7000u eDesign 2011 | B18: Elektriciteit | C18: Elektriciteitsopwekking | E18: 0 | F18: 0 | G18: 0 | H18: 0 | I18: 0 | J18: Gas fired with CCS
A19: 1017 Kolenvergassing CCS 7000u eDesign 2011 | B19: Kolen | C19: Elektriciteitsopwekking | E19: 0 | F19: 0 | G19: 0 | H19: 0 | I19: 0 | J19: Gas fired with CCS
A20: 1020 Solar thermal - Services | B20: Warmte | C20: HDO | D20: -5.0431666e-05 | E20: -0.0017069707 | F20: -0.0013633231 | G20: -9.4373294 | H20: -14.741707 | I20: -17.732528 | J20: Waste
A21: 1020 Solar thermal - Services | B21: Zon thermisch | C21: HDO | D21: 5.0431666e-05 | E21: 0.0017069707 | F21: 0.0013633231 | G21: 9.4373294 | H21: 14.741707 | I21: 17.732528 | J21: Solar PV - Industry
A22: 1021 Micro WKK brandstofcel Utiliteitsbouw eDesign 2011 | B22: Elektriciteit | C22: HDO | D22: 0 | E22: -2.5942992e-07 | F22: -1.6054678e-07 | G22: 0 | H22: -1.3949101e-06 | I22: -2.6027978e-07 | J22: Waste
A23: 1021 Micro WKK brandstofcel Utiliteitsbouw eDesign 2011 | B23: Warmte | C23: HDO | D23: 0 | E23: -2.5932067e-07 | F23: -2.3418511e-07 | G23: -1.1088828e-07 | H23: -2.2666754e-06 | I23: -3.7375714e-07 | J23: Nuclear
A24: 1021 Micro WKK brandstofcel Utiliteitsbouw eDesign 2011 | B24: Waterstof | C24: HDO | D24: 0 | E24: 2.5911911e-07 | F24: 3.7003776e-07 | G24: 1.8956861e-07 | H24: 3.8749634e-06 | I24: 5.8310737e-07 | J24: Nuclear
A25: 1022 Soil heat pump - Services | B25: Elektriciteit | C25: HDO | D25: 7.2727021e-06 | E25: 4.8629657e-05 | F25: 4.1408401e-05 | G25: 5.0047809e-07 | H25: 1.3344037e-05 | I25: 3.0030168e-05 | J25: Gas fired
A26: 1022 Soil heat pump - Services | B26: Omgevingswarmte | C26: HDO | D26: 1.273178e-05 | E26: 9.9401969e-05 | F26: 7.3425054e-05 | G26: 8.6072472e-07 | H26: 2.2949876e-05 | I26: 5.5732456e-05 | J26: Solar PV - Electricity sector
A27: 1022 Soil heat pump - Services | B27: Warmte | C27: HDO | D27: -1.9986278e-05 | E27: -0.0001341055 | F27: -0.00011253718 | G27: -1.3610514e-06 | H27: -3.6289119e-05 | I27: -8.1532055e-05 | J27: Solar PV - Agriculture
A28: 1023 Ground water heat pump - Services | B28: Aardgas | C28: HDO | D28: 0.14328119 | E28: 0.16541776 | F28: 0.19446466 | G28: 0.1555717 | H28: 0.02323769 | I28: 2.7408766e-06 | J28: Gas fired
A29: 1023 Ground water heat pump - Services | B29: Elektriciteit | C29: HDO | D29: 2.4459985 | E29: 2.8238955 | F29: 3.3197678 | G29: 2.6558143 | H29: 0.39669804 | I29: 4.5525305e-05 | J29: Gas fired
A30: 1023 Ground water heat pump - Services | B30: Omgevingswarmte | C30: HDO | D30: 10.999927 | E30: 12.699383 | F30: 14.929367 | G30: 11.943492 | H30: 1.7839952 | I30: 0.00020813957 | J30: Nuclear
A31: 1023 Ground water heat pump - Services | B31: Warmte | C31: HDO | D31: -13.58888 | E31: -15.688307 | F31: -18.443155 | G31: -14.754524 | H31: -2.203878 | I31: -0.00025255976 | J31: Nuclear
A32: 1024 Hybride WP ketel Utiliteitsbouw eDesign 2011 | B32: Aardgas | C32: HDO | D32: 0 | E32: 2.7397484e-07 | F32: 0 | G32: 0 | H32: 1.3024367e-06 | I32: 1.3071413e-07 | J32: Nuclear
A33: 1024 Hybride WP ketel Utiliteitsbouw eDesign 2011 | B33: Elektriciteit | C33: HDO | D33: 0 | E33: 2.6650238e-07 | F33: 0 | G33: 0 | H33: 6.2521599e-07 | I33: 1.0367535e-07
A34: 1024 Hybride WP ketel Utiliteitsbouw eDesign 2011 | B34: Omgevingswarmte | C34: HDO | D34: 0 | E34: 1.0551441e-05 | F34: 1.8203577e-06 | G34: 1.0883078e-07 | H34: 2.4173438e-06 | I34: 1.2496837e-05
A35: 1024 Hybride WP ketel Utiliteitsbouw eDesign 2011 | B35: Warmte | C35: HDO | D35: -1.188166e-07 | E35: -3.075051e-07 | F35: -1.642413e-07 | G35: -1.9553381e-07 | H35: -4.3412474e-06 | I35: -3.3075845e-07
A36: 1027 REF HR-107 - Services | B36: Aardgas | C36: HDO | D36: 0 | E36: 29.275181 | F36: 23.402685 | G36: 13.159088 | H36: 24.33852 | I36: 16.002826
A37: 1027 REF HR-107 - Services | B37: Warmte | C37: HDO | D37: 0 | E37: -26.991536 | F37: -21.593238 | G37: -11.971855 | H37: -22.142662 | I37: -14.559027
A38: 1029 Solar thermal - Newly built - Residential | B38: Warmte | C38: Huishoudens | D38: -4.4315563e-05 | E38: -0.007558223 | F38: -0.0061403542 | G38: -0.0049576441 | H38: -8.7762993e-05 | I38: -2.1285668e-05
A39: 1029 Solar thermal - Newly built - Residential | B39: Zon thermisch | C39: Huishoudens | D39: 4.4315563e-05 | E39: 0.007558223 | F39: 0.0061403542 | G39: 0.0049576441 | H39: 8.7762993e-05 | I39: 2.1285668e-05
A40: 1035 REF HR-107 - Existing - Residential | B40: Aardgas | C40: Huishoudens | D40: 252.30265 | E40: 216.22162 | F40: 195.97316 | G40: 184.0184 | H40: 164.215 | I40: 144.41443
...

Sheet Electricity & Heat
A1: Technology | B1: Energy Carrier | C1: 2025 | D1: 2030 | E1: 2035 | F1: 2040 | G1: 2045 | H1: 2050
A2: 1012 Solar-PV Residential | B2: Elektriciteit | C2: -37.080362 | D2: -29.859767 | E2: -30.326279 | F2: -47.025141 | G2: -31.259398 | H2: -48.450141
A3: 1012 Solar-PV Residential | B3: Zon | C3: 37.080362 | D3: 29.859767 | E3: 30.326279 | F3: 47.025141 | G3: 31.259398 | H3: 48.450141
A4: 1042 Wind op Zee band 1 | B4: Elektriciteit | C4: -81.121541 | D4: -188.90011 | E4: -232.98281 | F4: -232.76681 | G4: -306.86545 | H4: -307.3075
A5: 1042 Wind op Zee band 1 | B5: Wind | C5: 81.121542 | D5: 188.90011 | E5: 232.98281 | F5: 232.76681 | G5: 306.86545 | H5: 307.3075
A6: 1090 Wind op Land band 1 | B6: Elektriciteit | C6: -54.303554 | D6: -64.599915 | E6: -85.617193 | F6: -85.833189 | G6: -125.36606 | H6: -123.93943
A7: 1090 Wind op Land band 1 | B7: Wind | C7: 54.303554 | D7: 64.599937 | E7: 85.617197 | F7: 85.833189 | G7: 125.36606 | H7: 123.93944
A8: 1108 Natural gas CCGT | B8: Elektriciteit | C8: -57.797464 | D8: -98.607172 | E8: -55.524564 | F8: -39.162315 | G8: -39.297296 | H8: -39.986812
A9: 1108 Natural gas CCGT | B9: Aardgas | C9: 98.046953 | D9: 161.61715 | E9: 91.00476 | F9: 64.187034 | G9: 64.408269 | H9: 65.538384
A10: 1248 REF WKK gas Landbouw ebalans | B10: Elektriciteit | C10: -33.532452 | D10: -23.33348 | E10: -8.6327591e-06 | F10: -1.0904555e-07 | G10: -2.6269849e-06 | H10: -6.2927993e-06
A11: 1248 REF WKK gas Landbouw ebalans | B11: Aardgas | C11: 82.317601 | D11: 57.264511 | E11: 2.1294143e-05 | F11: 2.6996018e-07 | G11: 6.5065909e-06 | H11: 1.5470245e-05
A12: 1248 REF WKK gas Landbouw ebalans | B12: Warmte | C12: -39.395669 | D12: -27.401579 | E12: -1.0134695e-05 | F12: -1.2818319e-07 | G12: -3.0901081e-06 | H12: -7.3883457e-06
A13: 1462 Solar-PV Vertical (incl. bif noise barriers) | B13: Elektriciteit | C13: 0 | D13: -0.000128392 | E13: -6.1647548e-05 | F13: -10.767974 | G13: -11.30507 | H13: -11.473801
... A63: 2323 NG CHP - District heating | B63: Warmte | C63: -0.041090148 | D63: -0.0044012233 | E63: -0.0021605046 | F63: -0.0012597933 | G63: -2.5975578e-05 | H63: -6.0242647e-05
