Workbook

Sheet Final_Investments_Multiplied
A1: Technology | B1: Energy Carrier | C1: 2025_investment_multiplied | D1: 2030_investment_multiplied | E1: 2035_investment_multiplied | F1: 2040_investment_multiplied | G1: 2045_investment_multiplied | H1: 2050_investment_multiplied | I1: Sector
A2: 1003 Micro-WKK Brandstofcel 2011 (WB nieuwbouw) | B2: Elektriciteit | C2: 0 | F2: 0 | H2: 0 | I2: Huishoudens
A3: 1003 Micro-WKK Brandstofcel 2011 (WB nieuwbouw) | B3: Warmte | C3: 0 | F3: 0 | H3: 0 | I3: Huishoudens
A4: 1003 Micro-WKK Brandstofcel 2011 (WB nieuwbouw) | B4: Waterstof | C4: 7.4583782e-05 | F4: 0 | H4: 0 | I4: Huishoudens
A5: 1010 Micro-WKK Brandstofcel 2011 (WB bestaande bouw) | B5: Elektriciteit | I5: Huishoudens
A6: 1010 Micro-WKK Brandstofcel 2011 (WB bestaande bouw) | B6: Warmte | I6: Huishoudens
A7: 1010 Micro-WKK Brandstofcel 2011 (WB bestaande bouw) | B7: Waterstof | I7: Huishoudens
A8: 1012 Solar-PV Residential | B8: Elektriciteit | C8: 0 | D8: 0 | E8: 0 | F8: 0 | G8: 0 | H8: 0 | I8: Huishoudens
A9: 1012 Solar-PV Residential | B9: Zon | C9: 10844.679 | D9: 0 | E9: 0 | F9: 0 | G9: 0 | H9: 0 | I9: Huishoudens
A10: 1013 Biomassavergassing met CCS 7000u 2011 | B10: Biomassa (hout) | D10: 0 | E10: 0 | F10: 0 | G10: 0 | H10: 0 | I10: Elektriciteitsopwekking
A11: 1013 Biomassavergassing met CCS 7000u 2011 | B11: CO2Flow | D11: 0 | E11: 0 | F11: 0 | G11: 0 | H11: 0 | I11: Elektriciteitsopwekking
A12: 1013 Biomassavergassing met CCS 7000u 2011 | B12: Elektriciteit | D12: 0 | E12: 0 | F12: 0 | G12: 0 | H12: 0 | I12: Elektriciteitsopwekking
A13: 1016 ATR with CC | B13: Aardgas | C13: 0 | D13: 0.00048504449 | E13: 14.634192 | F13: 13.819752 | G13: 0 | H13: 0 | I13: H2 voorziening
A14: 1016 ATR with CC | B14: CO2Flow | C14: 0 | D14: 0 | E14: 0 | F14: 0 | G14: 0 | H14: 0 | I14: H2 voorziening
A15: 1016 ATR with CC | B15: Elektriciteit | C15: 0 | D15: 2.0211074e-05 | E15: 0.60979531 | F15: 0.64054696 | G15: 0 | H15: 0 | I15: H2 voorziening
A16: 1016 ATR with CC | B16: Waterstof | C16: 0 | D16: 0 | E16: 0 | F16: 0 | G16: 0 | H16: 0 | I16: H2 voorziening
A17: 1017 Kolenvergassing CCS 7000u eDesign 2011 | B17: CO2Flow | I17: Elektriciteitsopwekking
A18: 1017 Kolenvergassing CCS 7000u eDesign 2011 | B18: Elektriciteit | I18: Elektriciteitsopwekking
A19: 1017 Kolenvergassing CCS 7000u eDesign 2011 | B19: Kolen | I19: Elektriciteitsopwekking
A20: 1020 Solar thermal - Services | B20: Warmte | C20: 0 | D20: 0 | E20: 0 | F20: 0 | G20: 0 | H20: 0 | I20: HDO
A21: 1020 Solar thermal - Services | B21: Zon thermisch | C21: 0.0093235959 | D21: 0 | E21: 0 | F21: 6.5201602 | G21: 3.2823256 | H21: 1.6935916 | I21: HDO
A22: 1021 Micro WKK brandstofcel Utiliteitsbouw eDesign 2011 | B22: Elektriciteit | C22: 0 | F22: 0 | H22: 0 | I22: HDO
A23: 1021 Micro WKK brandstofcel Utiliteitsbouw eDesign 2011 | B23: Warmte | C23: 0 | F23: 0 | H23: 0 | I23: HDO
A24: 1021 Micro WKK brandstofcel Utiliteitsbouw eDesign 2011 | B24: Waterstof | C24: 5.7360763e-05 | F24: 0 | H24: 0 | I24: HDO
A25: 1022 Soil heat pump - Services | B25: Elektriciteit | C25: 0.0021375818 | D25: 0 | E25: 0 | F25: 0 | G25: 0 | H25: 0 | I25: HDO
A26: 1022 Soil heat pump - Services | B26: Omgevingswarmte | C26: 0.0037408227 | D26: 0 | E26: 0 | F26: 0 | G26: 0 | H26: 0 | I26: HDO
A27: 1022 Soil heat pump - Services | B27: Warmte | C27: 0 | D27: 0 | E27: 0 | F27: 0 | G27: 0 | H27: 0 | I27: HDO
A28: 1023 Ground water heat pump - Services | B28: Aardgas | C28: 29.596467 | D28: 0 | E28: 0 | F28: 0 | G28: 0 | H28: 0 | I28: HDO
A29: 1023 Ground water heat pump - Services | B29: Elektriciteit | C29: 505.24765 | D29: 0 | E29: 0 | F29: 0 | G29: 0 | H29: 0 | I29: HDO
A30: 1023 Ground water heat pump - Services | B30: Omgevingswarmte | C30: 2272.1574 | D30: 0 | E30: 0 | F30: 0 | G30: 0 | H30: 0 | I30: HDO
A31: 1023 Ground water heat pump - Services | B31: Warmte | C31: 0 | D31: 0 | E31: 0 | F31: 0 | G31: 0 | H31: 0 | I31: HDO
A32: 1024 Hybride WP ketel Utiliteitsbouw eDesign 2011 | B32: Aardgas | C32: 1.3913236e-05 | D32: 0 | E32: 0 | F32: 0 | G32: 0 | H32: 0 | I32: HDO
A33: 1024 Hybride WP ketel Utiliteitsbouw eDesign 2011 | B33: Elektriciteit | C33: 6.3072731e-06 | D33: 0 | E33: 0 | F33: 0 | G33: 0 | H33: 0 | I33: HDO
A34: 1024 Hybride WP ketel Utiliteitsbouw eDesign 2011 | B34: Omgevingswarmte | C34: 4.0422898e-05 | D34: 0 | E34: 0 | F34: 0 | G34: 8.8339836e-05 | H34: 0 | I34: HDO
A35: 1024 Hybride WP ketel Utiliteitsbouw eDesign 2011 | B35: Warmte | C35: 0 | D35: 0 | E35: 0 | F35: 0 | G35: 0 | H35: 0 | I35: HDO
A36: 1027 REF HR-107 - Services | B36: Aardgas | C36: 0 | D36: 13.138632 | E36: 0 | F36: 0 | G36: 0 | H36: 0 | I36: HDO
... A49: 1043 REF H2 uit SMR 2011 | B49: Waterstof | C49: 0 | D49: 0 | E49: 0 | F49: 0 | G49: 0 | H49: 0 | I49: H2 voorziening
A50: 1044 Ketels SHT kolen eDesign 2011 | B50: HeatHT400 | I50: Industrie
A51: 1044 Ketels SHT kolen eDesign 2011 | B51: Kolen | I51: Industrie
A52: 1045 Hydrogen Medium Temp Boilers - Industry | B52: Heat200to400 | C52: 0 | D52: 0 | E52: 0 | F52: 0 | G52: 0 | H52: 0 | I52: Industrie
...

Sheet Aggregated_By_Sector
A1: Sector | B1: Energy Carrier | C1: 2025_investment_multiplied | D1: 2030_investment_multiplied | E1: 2035_investment_multiplied | F1: 2040_investment_multiplied | G1: 2045_investment_multiplied | H1: 2050_investment_multiplied
A2: Basic metal non-ferro | B2: Aardgas | C2: 0 | D2: 0.010656754 | E2: 0 | F2: 0 | G2: 0 | H2: 0
A3: Basic metal non-ferro | B3: CO2Flow | C3: 0 | D3: 0 | E3: 0 | F3: 0 | G3: 0 | H3: 0
A4: Basic metal non-ferro | B4: Elektriciteit | C4: 4.9952826 | D4: 0.0066844832 | E4: 0.0031111093 | F4: 0 | G4: 0 | H4: 0
A5: Basic metal non-ferro | B5: Heat100to200 | C5: 0 | D5: 0 | E5: 0 | F5: 0 | G5: 0 | H5: 0
A6: Basic metal non-ferro | B6: Heat200to400 | C6: 0 | D6: 0 | E6: 0 | F6: 0 | G6: 0 | H6: 0
A7: Basic metal non-ferro | B7: HeatDir200to400 | C7: 0 | D7: 0 | E7: 0 | F7: 0 | G7: 0 | H7: 0
A8: Basic metal non-ferro | B8: HeatHT400 | C8: 0 | D8: 0 | E8: 0 | F8: 0 | G8: 0 | H8: 0
A9: Basic metal non-ferro | B9: Industrial Waste Heat | C9: 0 | D9: 0 | E9: 0 | F9: 0 | G9: 0 | H9: 0
A10: Basic metal non-ferro | B10: Omgevingswarmte | C10: 12.488206 | D10: 0 | E10: 0 | F10: 0 | G10: 0 | H10: 0
A11: Basic metal non-ferro | B11: Warmte | C11: 0 | D11: 0 | E11: 0 | F11: 0 | G11: 0 | H11: 0
A12: Basic metal non-ferro | B12: Waterstof | C12: 0 | D12: 0.00051652164 | E12: 0 | F12: 0 | G12: 0 | H12: 2.1069439e-05
A13: Basismetaal ferro | B13: Aardgas | C13: 0.00044493387 | D13: 48.40005 | E13: 0.025366557 | F13: 0 | G13: 0.016057227 | H13: 0.024268989
... A381: dummy | B381: Biomassa (hout) | C381: 0 | D381: 0 | E381: 0 | F381: 0 | G381: 0 | H381: 0

Sheet IND
A1: Variable | B1: Sector | C1: Unit | E1: 2025 | F1: 2030 | G1: 2035 | H1: 2040 | I1: 2045 | J1: 2050 | T1: Variable | U1: Sector | V1: Unit | X1: 2025 | Y1: 2030 | Z1: 2035 | AA1: 2040 | AB1: 2045 | AC1: 2050
A2: Investments | B2: IND01 | C2: th_euro | D2: ENE01 | E2: 0 | F2: 0 | G2: 0 | H2: 0 | I2: 0 | J2: 0
A3: Investments | B3: IND01 | C3: th_euro | D3: ENE02 | E3: 0 | F3: 0 | G3: 0 | H3: 0 | I3: 0 | J3: 0
A4: Investments | B4: IND01 | C4: th_euro | D4: ENE03 | E4: 0 | F4: 0 | G4: 0 | H4: 0 | I4: 0 | J4: 0 | T4: Energy Use | U4: AGR01 | V4: TJ | W4: ENE01 | X4: 0 | Y4: 0 | Z4: 0 | AA4: 0 | AB4: 0 | AC4: 0
A5: Investments | B5: IND01 | C5: th_euro | D5: ENE04 | E5: =(Aggregated_By_Sector!C2+Aggregated_By_Sector!C10+Aggregated_By_Sector!C12)*1000 -> 12488.206 | F5: =(Aggregated_By_Sector!D2+Aggregated_By_Sector!D10+Aggregated_By_Sector!D12)*1000 -> 11.173275 | G5: =(Aggregated_By_Sector!E2+Aggregated_By_Sector!E10+Aggregated_By_Sector!E12)*1000 -> 0 | H5: =(Aggregated_By_Sector!F2+Aggregated_By_Sector!F10+Aggregated_By_Sector!F12)*1000 -> 0 | I5: =(Aggregated_By_Sector!G2+Aggregated_By_Sector!G10+Aggregated_By_Sector!G12)*1000 -> 0 | J5: =(Aggregated_By_Sector!H2+Aggregated_By_Sector!H10+Aggregated_By_Sector!H12)*1000 -> 0.021069439 | T5: Energy Use | U5: AGR01 | V5: TJ | W5: ENE02 | X5: 0 | Y5: 0 | Z5: 0 | AA5: 0 | AB5: 0 | AC5: 0
A6: Investments | B6: IND01 | C6: th_euro | D6: ENE05 | E6: =(Aggregated_By_Sector!C4)*1000 -> 4995.2826 | F6: =(Aggregated_By_Sector!D4)*1000 -> 6.6844832 | G6: =(Aggregated_By_Sector!E4)*1000 -> 3.1111093 | H6: =(Aggregated_By_Sector!F4)*1000 -> 0 | I6: =(Aggregated_By_Sector!G4)*1000 -> 0 | J6: =(Aggregated_By_Sector!H4)*1000 -> 0 | T6: Energy Use | U6: AGR01 | V6: TJ | W6: ENE03 | X6: 0 | Y6: 0.040648532 | Z6: 0.054424899 | AA6: 0.00061527495 | AB6: 0.013188794 | AC6: 0.093390029
A7: Investments | B7: IND01 | C7: th_euro | D7: ENE06 | E7: 0 | F7: 0 | G7: 0 | H7: 0 | I7: 0 | J7: 0 | T7: Energy Use | U7: AGR01 | V7: TJ | W7: ENE04 | X7: 60360.902 | Y7: 1897.295 | Z7: 1774.5667 | AA7: 0.0021044038 | AB7: 862.44163 | AC7: 59.295381
A8: Investments | B8: IND01 | C8: th_euro | D8: ENE07 | E8: 0 | F8: 0 | G8: 0 | H8: 0 | I8: 0 | J8: 0 | T8: Energy Use | U8: AGR01 | V8: TJ | W8: ENE05 | X8: 10624.42 | Y8: 0 | Z8: 0 | AA8: 0 | AB8: 0 | AC8: 0
A9: Investments | B9: IND01 | C9: th_euro | D9: ENE08 | E9: 0 | F9: 0 | G9: 0 | H9: 0 | I9: 0 | J9: 0 | T9: Energy Use | U9: AGR01 | V9: TJ | W9: ENE06 | X9: 0 | Y9: 0.05055112 | Z9: 0 | AA9: 0 | AB9: 0 | AC9: 0
A10: Investments | B10: IND01 | C10: th_euro | D10: ENE09 | E10: 0 | F10: 0 | G10: 0 | H10: 0 | I10: 0 | J10: 0 | T10: Energy Use | U10: AGR01 | V10: TJ | W10: ENE07 | X10: 0.010965145 | Y10: 0 | Z10: 0 | AA10: 0 | AB10: 0 | AC10: 0
A11: Investments | B11: IND01 | C11: th_euro | D11: ENE10 | E11: 0 | F11: 0 | G11: 0 | H11: 0 | I11: 0 | J11: 0 | T11: Energy Use | U11: AGR01 | V11: TJ | W11: ENE08 | X11: 0 | Y11: 0 | Z11: 0 | AA11: 0 | AB11: 0 | AC11: 0
A12: Investments | B12: IND01 | C12: th_euro | D12: ENE11 | E12: 0 | F12: 0 | G12: 0 | H12: 0 | I12: 0 | J12: 0 | T12: Energy Use | U12: AGR01 | V12: TJ | W12: ENE09 | X12: 0 | Y12: 0 | Z12: 0 | AA12: 0 | AB12: 0 | AC12: 0
A13: Investments | B13: IND02 | C13: th_euro | D13: ENE01 | E13: 0 | F13: 0 | G13: 0 | H13: 0 | I13: 0 | J13: 0 | T13: Energy Use | U13: AGR01 | V13: TJ | W13: ENE10 | X13: 0 | Y13: 0 | Z13: 0 | AA13: 0 | AB13: 0 | AC13: 0
A14: Investments | B14: IND02 | C14: th_euro | D14: ENE02 | E14: 0 | F14: 0 | G14: 0 | H14: 0 | I14: 0 | J14: 0 | T14: Energy Use | U14: AGR01 | V14: TJ | W14: ENE11 | X14: 0 | Y14: 0 | Z14: 0 | AA14: 0 | AB14: 0 | AC14: 0
A15: Investments | B15: IND02 | C15: th_euro | D15: ENE03 | E15: 0 | F15: 0 | G15: 0 | H15: 0 | I15: 0 | J15: 0 | T15: Residential
A16: Investments | B16: IND02 | C16: th_euro | D16: ENE04 | E16: =(SUM(Aggregated_By_Sector!C13:C20)+SUM(Aggregated_By_Sector!C22:C32))*1000 -> 4174491.3 | F16: =(SUM(Aggregated_By_Sector!D13:D20)+SUM(Aggregated_By_Sector!D22:D32))*1000 -> 49013.469 | G16: =(SUM(Aggregated_By_Sector!E13:E20)+SUM(Aggregated_By_Sector!E22:E32))*1000 -> 29.70154 | H16: =(SUM(Aggregated_By_Sector!F13:F20)+SUM(Aggregated_By_Sector!F22:F32))*1000 -> 371.47098 | I16: =(SUM(Aggregated_By_Sector!G13:G20)+SUM(Aggregated_By_Sector!G22:G32))*1000 -> 16.057227 | J16: =(SUM(Aggregated_By_Sector!H13:H20)+SUM(Aggregated_By_Sector!H22:H32))*1000 -> 24.295078 | T16: Variable | U16: Sector | V16: Unit | X16: 2025 | Y16: 2030 | Z16: 2035 | AA16: 2040 | AB16: 2045 | AC16: 2050
A17: Investments | B17: IND02 | C17: th_euro | D17: ENE05 | E17: =(Aggregated_By_Sector!C21)*1000 -> 0.084104368 | F17: =(Aggregated_By_Sector!D21)*1000 -> 7283.6594 | G17: =(Aggregated_By_Sector!E21)*1000 -> 1.0475848 | H17: =(Aggregated_By_Sector!F21)*1000 -> 0 | I17: =(Aggregated_By_Sector!G21)*1000 -> 8.6491864 | J17: =(Aggregated_By_Sector!H21)*1000 -> 0
A18: Investments | B18: IND02 | C18: th_euro | D18: ENE06 | E18: 0 | F18: 0 | G18: 0 | H18: 0 | I18: 0 | J18: 0
A19: Investments | B19: IND02 | C19: th_euro | D19: ENE07 | E19: 0 | F19: 0 | G19: 0 | H19: 0 | I19: 0 | J19: 0 | T19: Energy Use | U19: Equipments | V19: TJ | W19: ENE01 | X19: 0 | Y19: 0 | Z19: 0 | AA19: 0 | AB19: 0 | AC19: 0
A20: Investments | B20: IND02 | C20: th_euro | D20: ENE08 | E20: 0 | F20: 0 | G20: 0 | H20: 0 | I20: 0 | J20: 0 | M20: 2025 | N20: 2030 | O20: 2035 | P20: 2040 | Q20: 2045 | R20: 2050 | T20: Energy Use | U20: Equipments | V20: TJ | W20: ENE02 | X20: 1465.0197 | Y20: 967.71765 | Z20: 869.80192 | AA20: 803.23731 | AB20: 788.7671 | AC20: 771.8378
A21: Investments | B21: IND02 | C21: th_euro | D21: ENE09 | E21: 0 | F21: 0 | G21: 0 | H21: 0 | I21: 0 | J21: 0 | T21: Energy Use | U21: Equipments | V21: TJ | W21: ENE03
A22: Investments | B22: IND02 | C22: th_euro | D22: ENE10 | E22: 0 | F22: 0 | G22: 0 | H22: 0 | I22: 0 | J22: 0 | N22: 0 | O22: 0 | P22: 0 | Q22: 0 | R22: 0 | T22: Energy Use | U22: Equipments | V22: TJ | W22: ENE04 | X22: 252410.08 | Y22: 233942.87 | Z22: 224800.57 | AA22: 198902.23 | AB22: 177597.11 | AC22: 156191.34
A23: Investments | B23: IND02 | C23: th_euro | D23: ENE11 | E23: 0 | F23: 0 | G23: 0 | H23: 0 | I23: 0 | J23: 0
A24: Investments | B24: IND04 | C24: th_euro | D24: ENE01 | E24: 0 | F24: 0 | G24: 0 | H24: 0 | I24: 0 | J24: 0 | T24: Energy Use | U24: Equipments | V24: TJ | W24: ENE06 | X24: 16000 | Y24: 11844.511 | Z24: 11305.711 | AA24: 11306.96 | AB24: 11311.852 | AC24: 11304.311
A25: Investments | B25: IND04 | C25: th_euro | D25: ENE02 | E25: 0 | F25: 0 | G25: 0 | H25: 0 | I25: 0 | J25: 0 | T25: Energy Use | U25: Equipments | V25: TJ | W25: ENE07 | X25: 0 | Y25: 0.19531542 | Z25: 0.070579573 | AA25: 0.36566069 | AB25: 2411.6025 | AC25: 1776.896
A26: Investments | B26: IND04 | C26: th_euro | D26: ENE03 | E26: 0 | F26: 0 | G26: 0 | H26: 0 | I26: 0 | J26: 0 | T26: Energy Use | U26: Equipments | V26: TJ | W26: ENE08 | X26: 0 | Y26: 0 | Z26: 0 | AA26: 0 | AB26: 0 | AC26: 0
A27: Investments | B27: IND04 | C27: th_euro | D27: ENE04 | E27: =(SUM(Aggregated_By_Sector!C80:C92)+Aggregated_By_Sector!C78+SUM(Aggregated_By_Sector!C97:C126)+Aggregated_By_Sector!C94+Aggregated_By_Sector!C95+SUM(Aggregated_By_Sector!C262:C268)+SUM(Aggregated_By_Sector!C255:C259))*1000+((Aggregated_By_Sector!C93+Aggregated_By_Sector!C260)*1000) -> 3720373.2 | F27: =(SUM(Aggregated_By_Sector!D80:D92)+Aggregated_By_Sector!D78+SUM(Aggregated_By_Sector!D97:D126)+Aggregated_By_Sector!D94+Aggregated_By_Sector!D95+SUM(Aggregated_By_Sector!D262:D268)+SUM(Aggregated_By_Sector!D255:D259))*1000+((Aggregated_By_Sector!D93+Aggregated_By_Sector!D260)*1000) -> 24361.678 | G27: =(SUM(Aggregated_By_Sector!E80:E92)+Aggregated_By_Sector!E78+SUM(Aggregated_By_Sector!E97:E126)+Aggregated_By_Sector!E94+Aggregated_By_Sector!E95+SUM(Aggregated_By_Sector!E262:E268)+SUM(Aggregated_By_Sector!E255:E259))*1000+((Aggregated_By_Sector!E93+Aggregated_By_Sector!E260)*1000) -> 1591.1443 | H27: =(SUM(Aggregated_By_Sector!F80:F92)+Aggregated_By_Sector!F78+SUM(Aggregated_By_Sector!F97:F126)+Aggregated_By_Sector!F94+Aggregated_By_Sector!F95+SUM(Aggregated_By_Sector!F262:F268)+SUM(Aggregated_By_Sector!F255:F259))*1000+((Aggregated_By_Sector!F93+Aggregated_By_Sector!F260)*1000) -> 1423.1239 | I27: =(SUM(Aggregated_By_Sector!G80:G92)+Aggregated_By_Sector!G78+SUM(Aggregated_By_Sector!G97:G126)+Aggregated_By_Sector!G94+Aggregated_By_Sector!G95+SUM(Aggregated_By_Sector!G262:G268)+SUM(Aggregated_By_Sector!G255:G259))*1000+((Aggregated_By_Sector!G93+Aggregated_By_Sector!G260)*1000) -> 541.16507 | J27: =(SUM(Aggregated_By_Sector!H80:H92)+Aggregated_By_Sector!H78+SUM(Aggregated_By_Sector!H97:H126)+Aggregated_By_Sector!H94+Aggregated_By_Sector!H95+SUM(Aggregated_By_Sector!H262:H268)+SUM(Aggregated_By_Sector!H255:H259))*1000+((Aggregated_By_Sector!H93+Aggregated_By_Sector!H260)*1000) -> 139392.69 | T27: Energy Use | U27: Equipments | V27: TJ | W27: ENE09 | X27: 0 | Y27: 1.4252682e-05 | Z27: 4.1136967e-06 | AA27: 8.681163e-08 | AB27: 1.8384283 | AC27: 2.0941156
A28: Investments | B28: IND04 | C28: th_euro | D28: ENE05 | E28: =(Aggregated_By_Sector!C96+Aggregated_By_Sector!C261)*1000 -> 136716.81 | F28: =(Aggregated_By_Sector!D96+Aggregated_By_Sector!D261)*1000 -> 1256.2759 | G28: =(Aggregated_By_Sector!E96+Aggregated_By_Sector!E261)*1000 -> 1880.6304 | H28: =(Aggregated_By_Sector!F96+Aggregated_By_Sector!F261)*1000 -> 46.411126 | I28: =(Aggregated_By_Sector!G96+Aggregated_By_Sector!G261)*1000 -> 0.055435188 | J28: =(Aggregated_By_Sector!H96+Aggregated_By_Sector!H261)*1000 -> 19689.245 | K28: =(SUM(E24:E36)=(SUM(Aggregated_By_Sector!C78:C126)+SUM(Aggregated_By_Sector!C255:C268))*1000) -> TRUE | T28: Energy Use | U28: Equipments | V28: TJ | W28: ENE10 | X28: 0.014134539 | Y28: 9.2463592 | Z28: 3.1531051 | AA28: 4.1052399 | AB28: 2.2750715 | AC28: 1.0792212
A29: Investments | B29: IND04 | C29: th_euro | D29: ENE06 | E29: 0 | F29: 0 | G29: 0 | H29: 0 | I29: 0 | J29: 0 | T29: Energy Use | U29: Equipments | V29: TJ | W29: ENE11 | Z29: 5.5175528e-07 | AA29: 1.9531129e-08 | AB29: 0.34481905 | AC29: 0.24224625
A30: Investments | B30: IND04 | C30: th_euro | D30: ENE07 | E30: 0 | F30: 0 | G30: 0 | H30: 0 | I30: 0 | J30: 0
A31: Investments | B31: IND04 | C31: th_euro | D31: ENE08 | E31: 0 | F31: 0 | G31: 0 | H31: 0 | I31: 0 | J31: 0
A32: Investments | B32: IND04 | C32: th_euro | D32: ENE09 | E32: 0 | F32: 0 | G32: 0 | H32: 0 | I32: 0 | J32: 0 | U32: 2025 | V32: 2030 | W32: 2035 | X32: 2040 | Y32: 2045 | Z32: 2050 | AA32: 2050x
A33: Investments | B33: IND04 | C33: th_euro | D33: ENE10 | E33: 0 | F33: 0 | G33: 0 | H33: 0 | I33: 0 | J33: 0 | S33: Vehicle | T33: Electric vehicle | V33: 0.0092307222 | W33: 0.009760311 | X33: 0.21849991 | Y33: 0.029355662 | Z33: 0.4462629 | AA33: 0.11156572
A34: Investments | B34: IND04 | C34: th_euro | D34: CCS | E34: 0 | F34: 0 | G34: 0 | H34: 0 | I34: 0 | J34: 0
A35: Investments | B35: IND04 | C35: th_euro | D35: Geothermal | E35: =(Aggregated_By_Sector!C79)*1000 -> 0.16899602 | F35: =(Aggregated_By_Sector!D79)*1000 -> 0.85470119 | G35: =(Aggregated_By_Sector!E79)*1000 -> 0.5993742 | H35: =(Aggregated_By_Sector!F79)*1000 -> 0 | I35: =(Aggregated_By_Sector!G79)*1000 -> 0 | J35: =(Aggregated_By_Sector!H79)*1000 -> 0
A36: Investments | B36: IND04 | C36: th_euro | D36: ENE11 | E36: 0 | F36: 0 | G36: 0 | H36: 0 | I36: 0 | J36: 0 | T36: ICE | V36: 0 | W36: 0 | X36: 1446721.9 | Y36: 0 | Z36: 0 | AA36: 0
A37: Investments | B37: IND08 | C37: th_euro | D37: ENE01 | E37: 0 | F37: 0 | G37: 0 | H37: 0 | I37: 0 | J37: 0 | T37: Hybrid | V37: 575030.44 | W37: 0 | X37: 0 | Y37: 0 | Z37: 0 | AA37: 0
A38: Investments | B38: IND08 | C38: th_euro | D38: ENE02 | E38: 0 | F38: 0 | G38: 0 | H38: 0 | I38: 0 | J38: 0 | T38: Hydrogen | V38: 620.1839 | W38: 0 | X38: 0 | Y38: 0 | Z38: 0 | AA38: 0
A39: Investments | B39: IND08 | C39: th_euro | D39: ENE03 | E39: 0 | F39: 0 | G39: 0 | H39: 0 | I39: 0 | J39: 0
A40: Investments | B40: IND08 | C40: th_euro | D40: ENE04 | E40: =(Final_Investments_Multiplied!C1694+Final_Investments_Multiplied!C1696+Final_Investments_Multiplied!C1700)*1000 -> 516966.83 | F40: =(Final_Investments_Multiplied!D1694+Final_Investments_Multiplied!D1696+Final_Investments_Multiplied!D1700)*1000 -> 0.0040108467 | G40: =(Final_Investments_Multiplied!E1694+Final_Investments_Multiplied!E1696+Final_Investments_Multiplied!E1700)*1000 -> 0.0010907355 | H40: =(Final_Investments_Multiplied!F1694+Final_Investments_Multiplied!F1696+Final_Investments_Multiplied!F1700)*1000 -> 0 | I40: =(Final_Investments_Multiplied!G1694+Final_Investments_Multiplied!G1696+Final_Investments_Multiplied!G1700)*1000 -> 0 | J40: =(Final_Investments_Multiplied!H1694+Final_Investments_Multiplied!H1696+Final_Investments_Multiplied!H1700)*1000 -> 0.00088025532 | K40: =SUM(E37:J47)=SUM(Final_Investments_Multiplied!C1694:H1702)*1000 -> TRUE
...

Sheet info
B3: PGT01 | C3: Coal fired | F3: ENE01 | G3: Coal
B4: PGT02 | C4: Oil fired | F4: ENE02 | G4: Crude Oil
B5: PGT03 | C5: Gas fired | F5: ENE03 | G5: Oil
B6: PGT04 | C6: Nuclear | F6: ENE04 | G6: Gas
B7: PGT05 | C7: Biomass | F7: ENE05 | G7: Power Supply
B8: PGT06 | C8: Hydro electric | F8: ENE06 | G8: Biomass Solid
B9: PGT07 | C9: Wind | F9: ENE07 | G9: Biofuels
B10: PGT08 | C10: PV | F10: ENE08 | G10: Clean Gas
B11: PGT09 | C11: Geothermal | F11: ENE09 | G11: Green Hydrogen
B12: PGT10 | C12: CCS coal | F12: ENE10 | G12: Blue Hydrogen
B13: PGT11 | C13: CCS Gas | F13: ENE11 | G13: Storage of Green Hydrogen
B14: PGT12 | C14: CCS Bio
F16: TRA01 | G16: Air transport
B17: IND01 | C17: Ferrous metals | F17: TRA02 | G17: Land transport
B18: IND02 | C18: Non-ferrous metals | F18: TRA03 | G18: Water transport
B19: IND03 | C19: Fabricated Metal products
B20: IND04 | C20: Chemical Products
B21: IND05 | C21: Basic pharmaceutical products
B22: IND06 | C22: Rubber and plastic products
B23: IND07 | C23: Paper products, publishing
B24: IND08 | C24: Non-metallic minerals
B25: IND09 | C25: Computer, electronic and optical products
B26: IND10 | C26: Transport equipment (excluding EV)
B27: IND11 | C27: Other Equipment Goods
B28: IND12 | C28: Consumer Goods Industries
B29: IND13 | C29: Construction
B30: IND14 | C30: Batteries
... B38: IND22 | C38: Pipeline network of Hydrogen
