Workbook

Sheet General Information
B2: Scenario code: | C2: TRANSFORM
B3: Bron profielen: | C3: Flexnet
B4: Timeslice indicator: | C4: AVDiff-TimeAwareDayEveningNightSeasonXtrReserved
B5: # Timeslices step 1: | C5: 85
B6: Year: | C6: 2035
B7: # Options: | C7: 884
B8: Hour Resolution: | C8: Not applicable
B9: Model: | C9: Opera
B10: Version: | C10: 2023.1
B11: Time stamp: | C11: 27-03-2025 09:57
B12: Type of run: | C12: Static model
B14: Solver: | C14: GUROBI 9.1
B15: CrossOverStep1: | C15: Off
B16: NumericFocusStep1: | C16: 1
B17: Hom. Algorithm Step1: | C17: On
B18: Mode step 2: | C18: Not applicable
B19: # Timeslices Step 2: | C19: Not applicable
B20: CrossOverStep2: | C20: Not applicable
B21: NumericFocusStep2: | C21: Not applicable
B22: Hom. Algorithm Step2: | C22: Not applicable

Sheet Summary
A2: Main indicators | F2: Net consumption [PJ] / Primary energy [PJ] | Q2: Primary energy [PJ]
A4: Indicator | B4: Unit | C4: Value | H4: KIP built environment | I4: KIP energy | J4: KIP agriculture | K4: KIP transport | L4: KIP industry | M4: KIP bunkers | N4: LULUCF | O4: Total net consumption | R4: Bunkers | S4: Feedstock | T4: Total | U4: Total, excl. BFFS | V4: EED | Y4: pFinalEnergyDataTot_Eagg
A5: Total GHG emissions | B5: [Mton CO2eq] | C5: 88.358666 | F5: Netto levering(+ verbruik, - productie) | G5: Warmte | H5: 31.778022 | I5: -9.9366663 | J5: 0.033330082 | K5: -8.5451571e-08 | L5: -21.874756 | M5: 0 | N5: 0 | O5: =SUM(H5:N5) -> -7.0228983e-05 | Q5: Warmte | R5: 9.5122877e-06 | S5: 6.202301e-06 | T5: -7.0228983e-05 | U5: -8.5943572e-05 | V5: -7.0228983e-05
A6: Shadow price CO2 | B6: [€/ton] | C6: 0 | G6: Waterstof | H6: 0.0038427522 | I6: 0.00010893526 | J6: 0 | K6: 0.021746282 | L6: -0.02570361 | M6: 0 | N6: 0 | O6: =SUM(H6:N6) -> -5.6409034e-06 | Q6: Waterstof | R6: 2.3912096e-05 | S6: 7.7994142e-05 | T6: -5.6409034e-06 | U6: -0.00010754714 | V6: -0.53161224
A7: Total system cost | B7: [M€/yr] | C7: 86376.288 | G7: Elektriciteit | H7: 152.33089 | I7: -389.34124 | J7: 43.446171 | K7: 60.127335 | L7: 162.8293 | M7: 0 | N7: 0 | O7: =SUM(H7:N7) -> 29.392449 | Q7: Elektriciteit | R7: 0.42270492 | S7: 0.30736603 | T7: 54.034763 | U7: 53.304692 | V7: 29.392452
A8: Penetration Wind | B8: [GWe] | C8: 21.190971 | G8: Afval (niet-biogeen) | H8: 0 | I8: 0 | J8: 0 | K8: 0 | L8: 25.698003 | M8: 0 | N8: 0 | O8: =SUM(H8:N8) -> 25.698003 | Q8: Afval (niet-biogeen) | R8: 0.15499698 | S8: 0.11272844 | T8: 25.698003 | U8: 25.430277 | V8: 25.698003
A9: Penetration Wind | B9: [TWh/yr] | C9: 88.500002 | G9: Aardgas | H9: 290.51992 | I9: 115.81359 | J9: 5.0027179 | K9: 2.4315968 | L9: 251.85237 | M9: 123.29986 | N9: 0 | O9: =SUM(H9:N9) -> 788.92006 | Q9: Aardgas | R9: 140.7312 | S9: 66.203551 | T9: 788.92006 | U9: 581.9853 | V9: 609.13889
A10: Penetration Solar PV | B10: [GWe] | C10: 33.967177 | G10: Aardwarmte | H10: 0 | I10: 0.79997676 | J10: 24.189351 | K10: 0 | L10: 1.0106738 | M10: 0 | N10: 0 | O10: =SUM(H10:N10) -> 26.000002 | Q10: Aardwarmte | R10: 0.0010051083 | S10: 0.00030814107 | T10: 26.000002 | U10: 25.998688 | V10: 26.000002
A11: Penetration Solar PV | B11: [TWh/yr] | C11: 30.089556 | G11: Ammonia | H11: 0 | I11: 0 | J11: 0 | K11: 0 | L11: 0.10005027 | M11: 0 | N11: 0 | O11: =SUM(H11:N11) -> 0.10005027 | Q11: Ammonia | R11: 1.4245609e-06 | S11: 0.10004351 | T11: 0.10005027 | U11: 5.3324326e-06 | V11: 7.6450637e-06
A12: Curtailment Wind | B12: [TWh/yr] | C12: 11.57541 | G12: Biobrandstoffen | H12: 0 | I12: 0 | J12: 0 | K12: 9.4372872 | L12: -21.9089 | M12: 21.996599 | N12: 0 | O12: =SUM(H12:N12) -> 9.5249865 | Q12: Biobrandstoffen | R12: 0.2819509 | S12: 0.34738756 | T12: 9.5249865 | U12: 8.895648 | V12: -10.99782
A13: Curtailment Wind | B13: [%] | C13: 11.566688 | G13: Biogas | H13: 0.00034101887 | I13: 0 | J13: 15 | K13: 0 | L13: 23.699749 | M13: 0 | N13: 0 | O13: =SUM(H13:N13) -> 38.70009 | Q13: Biogas | R13: 0.40057927 | S13: 1.4961857 | T13: 38.70009 | U13: 36.803325 | V13: 38.70009
A14: Curtailment Solar PV | B14: [TWh/yr] | C14: 0 | G14: Biomassa | H14: 11.307015 | I14: 0.00011959194 | J14: 0 | K14: 0 | L14: 106.03651 | M14: 0 | N14: 0 | O14: =SUM(H14:N14) -> 117.34364 | Q14: Biomassa | R14: 22.277323 | S14: 5.2047491 | T14: 117.34364 | U14: 89.861571 | V14: 117.34364
A15: Curtailment Solar PV | B15: [%] | C15: 0 | G15: Kolen | H15: 0 | I15: 0 | J15: 0 | K15: 0 | L15: 45.368588 | M15: 0 | N15: 0 | O15: =SUM(H15:N15) -> 45.368588 | Q15: Kolen | R15: 0.21696605 | S15: 0.14244535 | T15: 45.368588 | U15: 45.009177 | V15: 45.368588
A16: Electrolysis | B16: [GWe] | C16: 1.4465324e-05 | G16: Olie | H16: 0.87095578 | I16: 0 | J16: 5.4424899e-05 | K16: 313.7363 | L16: 643.78452 | M16: 408.18616 | N16: 0 | O16: =SUM(H16:N16) -> 1366.578 | Q16: Olie | R16: 385.36437 | S16: 415.52692 | T16: 1366.578 | U16: 565.6867 | V16: 667.24302
A17: Electrolysis | B17: [TWhe/yr] (input) | C17: 3.7858345e-05 | G17: Omgevingswarmte | H17: 48.858891 | I17: 0.40105508 | J17: 1.839996 | K17: 0 | L17: 9.5000069 | M17: 0 | N17: 0 | O17: =SUM(H17:N17) -> 60.599949 | Q17: Omgevingswarmte | R17: 4.867919e-07 | S17: 1.4922265e-07 | T17: 60.599949 | U17: 60.599949 | V17: 0
... A23: Electricity export | B23: [TWh/yr] | C23: 6.8450874 | G23: Zon thermisch | H23: 0.18901593 | I23: 7.2875689e-05 | J23: 0 | K23: 0 | L23: 2.0150209e-05 | M23: 0 | N23: 0 | O23: =SUM(H23:N23) -> 0.18910896 | Q23: Zon thermisch | R23: 1.5190889e-09 | S23: 4.6566606e-10 | T23: 0.18910896 | U23: 0.18910896 | V23: 0.18910896
A24: Hydrogen import | B24: [TWh/yr] | C24: 0 | G24: Totaal | H24: 603.39975 | I24: 103.53895 | J24: 96.43139 | K24: 386.03613 | L24: 1230.4654 | M24: 553.88004 | N24: 0 | O24: =SUM(O5:O23) -> 2973.7517
A25: Hydrogen export | B25: [TWh/yr] | C25: 0
A26: CCS | B26: [Mton CO2] | C26: 10.500004
A27: CCU | B27: [Mton CO2] | C27: 0.12988494
A28: Dispatchable power capacity | B28: [GWe] | C28: 20.840173

Sheet GHG emissions
A3: GHG emissions [Mton CO2-eq] per sector (Excluding emissions from aviation and international shipping!)
B5: TRANSFORM
B6: KIP built environment | C6: KIP energy | D6: KIP agriculture | E6: KIP transport | F6: KIP industry | G6: LULUCF
A7: Total GHG emissions | B7: 17.178973 | C7: 6.5550496 | D7: 8.8637532 | E7: 23.339739 | F7: 29.337152 | G7: 3.0839998 | I7: =SUM(B7:G7) -> 88.358666 | J7: Sum of all Green House Gasses (excl. Aviation and international shipping)
A8: GHG emissions - energy carrier related | B8: 16.507009 | C8: 6.5550496 | D8: 0.28315746 | E8: 22.969287 | F8: 35.854684 | G8: 0 | I8: =SUM(B8:G8) -> 82.169187 | J8: Sum all GHG emissions related to consumption of energy carriers. Sum of line 8 and 9 add up to 7.
A9: GHG emissions - Non energy and Process related | B9: 0 | C9: 0 | D9: 0 | E9: 0 | F9: 0 | G9: 0 | I9: =SUM(B9:G9) -> 0 | J9: Sum all process GHG and negative emissions because of storage in chemicals, plastics, etc.. Sum of line 8 and 9 add up to 7.
A10: Total emissions - CO2 | B10: 16.806835 | C10: 6.5550496 | D10: 0.46117296 | E10: 22.969287 | F10: 27.156585 | G10: 3.0839998 | I10: =SUM(B10:G10) -> 77.032929 | J10: CO2 part of GHG emissions. Sum of line 10 and 11 adds up to line 7.
A11: Total emissions - Other GHG | B11: 0.37213799 | C11: 0 | D11: 8.4025802 | E11: 0.37045203 | F11: 2.1805669 | G11: 0 | I11: =SUM(B11:G11) -> 11.325737 | J11: Other GHG emissions part of GHG emissions. Sum of line 10 and 11 adds up to line 7.
A12: CCS [Mton] | B12: 0 | C12: 0 | D12: 0 | E12: 0 | F12: 10.500004 | G12: 0 | I12: =SUM(B12:G12) -> 10.500004 | J12: Total amount of CO2 captured using CCS
A15: Corrected, so all CO2 storage is allocated to the sectors, based on the storage/capture ratio
B17: KIP agriculture | C17: KIP built environment | D17: KIP bunkers | E17: KIP energy | F17: KIP industry | G17: KIP transport
A18: Total GHG emissions | B18: =B19+B20 -> 0.83331096 | C18: =C19+C20 -> 16.806835 | D18: =D19+D20 -> 8.4025802 | E18: =E19+E20 -> 6.9254669 | F18: =F19+F20 -> 29.337187 | G18: =G19+G20 -> 22.969287 | I18: =SUM(B18:G18) -> 85.274666
A19: Total emissions - CO2 | B19: ='CO2 emissions per sector'!K33 -> 0.46117297 | C19: ='CO2 emissions per sector'!L33 -> 16.806835 | D19: ='CO2 emissions per sector'!M33 -> 0 | E19: ='CO2 emissions per sector'!N33 -> 6.5550149 | F19: ='CO2 emissions per sector'!O33 -> 27.15662 | G19: ='CO2 emissions per sector'!P33 -> 22.969287 | I19: =SUM(B19:G19) -> 73.948929
A20: Total emissions - Other GHG | B20: =B11 -> 0.37213799 | C20: =C11 -> 0 | D20: =D11 -> 8.4025802 | E20: =E11 -> 0.37045203 | F20: =F11 -> 2.1805669 | G20: =G11 -> 0 | I20: =SUM(B20:G20) -> 11.325737
A21: CCS [Mton] | B21: ='CO2 emissions per sector'!K34 -> 0 | C21: ='CO2 emissions per sector'!L34 -> 0 | D21: ='CO2 emissions per sector'!M34 -> 0 | E21: ='CO2 emissions per sector'!N34 -> 3.4653138e-05 | F21: ='CO2 emissions per sector'!O34 -> 10.499966 | G21: ='CO2 emissions per sector'!P34 -> 0 | I21: =SUM(B21:G21) -> 10.500001
A24: GHG emissions per type[Mton CO2-eq] (Including emissions from aviation and international shipping)
B26: GHG emissions per type [Mton CO2-eq]
B28: 149.24001
A29: CO2 | B29: 77.032929
A30: CH4 | B30: 6.7038762
A31: N2O | B31: 3.9184315
A32: F-gassen | B32: 0.68684857
A33: CO2, shipping | B33: 32.547891
A34: CO2, aviation | B34: 9.9971522
A35: CO2, LULUCF | B35: 0
A36: Total [Mton CO2-eq] | B36: =SUM(B29:B35) -> 130.88713

Sheet Service Demand
A2: Service demands (activities) | B2: Activity specific units (ie Mton staal), but in case PJ, it might mean simply one unit of activity, for example 1.0 ''PJ" for AVI means all (=1,0 in this case) municipal solid waste is combusted.
A4: Service demand | B4: Option | C4: v | D4: zj | E4: Activity Baseline | F4: Activitity Run | G4: Unit Activity | H4: Capacity Baseline | I4: Capacity Run | J4: Unit Capacity
A5: Energy in education | B5: 2190 Energy in education - GFE label | C5: 1 | D5: 2035 | E5: 0.8406 | F5: 0.0005 | G5: km2 GFA | H5: 0.063 | I5: 0.0005 | J5: km2 GFA
A6: Energy in education | B6: 2191 Energy in education - DC label | C6: 1 | D6: 2035 | F6: 14.2298 | G6: km2 GFA | I6: 14.2297 | J6: km2 GFA
A7: Energy in education | B7: 2192 Energy in education - B label | C7: 1 | D7: 2035 | F7: 5.7003 | G7: km2 GFA | I7: 5.7003 | J7: km2 GFA
A8: Energy in education | B8: 2193 Energy in education - A label | C8: 1 | D8: 2035 | F8: 1.5737 | G8: km2 GFA | I8: 1.5737 | J8: km2 GFA
A9: Energy in education | B9: 2194 Energy in education - A+ label | C9: 1 | D9: 2035 | F9: 9.9946 | G9: km2 GFA | I9: 9.9946 | J9: km2 GFA
A10: Energy in hospitals | B10: 2201 Energy in hospitals - DC label | C10: 1 | D10: 2035 | F10: 11.0272 | G10: km2 GFA | I10: 11.0272 | J10: km2 GFA
A11: Energy in hospitals | B11: 2202 Energy in hospitals - B label | C11: 1 | D11: 2035 | F11: 3.8952 | G11: km2 GFA | I11: 3.8952 | J11: km2 GFA
A12: Energy in hospitals | B12: 2203 Energy in hospitals - A label | C12: 1 | D12: 2035 | F12: 1.3325 | G12: km2 GFA | I12: 1.3325 | J12: km2 GFA
A13: Energy in hospitals | B13: 2204 Energy in hospitals - A+ label | C13: 1 | D13: 2035 | F13: 7.126 | G13: km2 GFA | I13: 7.126 | J13: km2 GFA
A14: Energy in industrial halls | B14: 2196 Energy in industrial halls - DC label | C14: 1 | D14: 2035 | F14: 128.1773 | G14: km2 GFA | I14: 128.1773 | J14: km2 GFA
A15: Energy in industrial halls | B15: 2197 Energy in industrial halls - B label | C15: 1 | D15: 2035 | F15: 27.2023 | G15: km2 GFA | I15: 27.2023 | J15: km2 GFA
A16: Energy in industrial halls | B16: 2198 Energy in industrial halls - A label | C16: 1 | D16: 2035 | F16: 0.0009 | G16: km2 GFA | I16: 0.0008 | J16: km2 GFA
A17: Energy in industrial halls | B17: 2199 Energy in industrial halls - A+ label | C17: 1 | D17: 2035 | F17: 28.8066 | G17: km2 GFA | I17: 28.8066 | J17: km2 GFA
... A28: Energy in apartments with startlabel DC and B | B28: 2178 Apartments - startlabel DC | C28: 1 | D28: 2035 | F28: 0.3249 | G28: M apartments | I28: 0.3252 | J28: M apartments
A29: Energy in apartments with startlabel DC and B | B29: 2179 Apartments - startlabel DC/B retrofitted to A | C29: 1 | D29: 2035 | G29: M apartments | I29: 0 | J29: M apartments
A30: Energy in apartments with startlabel GFE | B30: 2400 Apartments - startlabel GFE retrofitted to DC | C30: 1 | D30: 2035 | F30: 0.6792 | G30: M apartments | I30: 0.6792 | J30: M apartments
A31: Energy in apartments with startlabel GFE | B31: 2401 Apartments - startlabel GFE retrofitted to B | C31: 1 | D31: 2035 | F31: 0 | G31: M apartments | I31: 0 | J31: M apartments
A32: Energy in other dwellings with startlabel A | B32: 2183 Other dwelllings - startlabel A | C32: 1 | D32: 2035 | F32: 0.4534 | G32: M other dwellings | I32: 0.4534 | J32: M other dwellings
A33: Energy in other dwellings with startlabel A | B33: 2396 Other dwelllings - startlabel A retrofitted to A+ | C33: 1 | D33: 2035 | F33: 0 | G33: M other dwellings | I33: 0 | J33: M other dwellings
A34: Energy in other dwellings with startlabel A+ | B34: 2184 Other dwelllings - startlabel A+ | C34: 1 | D34: 2035 | F34: 0.5261 | G34: M other dwellings | I34: 0.5261 | J34: M other dwellings
A35: Energy in other dwellings with startlabel DC and B | B35: 2173 Other dwelllings - startlabel B or DC retrofitted to B | C35: 1 | D35: 2035 | F35: 1.0843 | G35: M other dwellings | I35: 1.084 | J35: M other dwellings
A36: Energy in other dwellings with startlabel DC and B | B36: 2182 Other dwelllings - startlabel DC | C36: 1 | D36: 2035 | F36: 0.2846 | G36: M other dwellings | I36: 0.2849 | J36: M other dwellings
A37: Energy in other dwellings with startlabel DC and B | B37: 2398 Other dwelllings - startlabel DC/B retrofitted to A | C37: 1 | D37: 2035 | F37: 0 | G37: M other dwellings | I37: 0 | J37: M other dwellings
A38: Energy in other dwellings with startlabel GFE | B38: 2402 Other dwelllings - startlabel GFE retrofitted to DC | C38: 1 | D38: 2035 | F38: 0.6056 | G38: M other dwellings | I38: 0.6056 | J38: M other dwellings
A39: Energy in other dwellings with startlabel GFE | B39: 2403 Other dwelllings - startlabel GFE retrofitted to B | C39: 1 | D39: 2035 | G39: M other dwellings | I39: 0 | J39: M other dwellings
A40: Energy in terraced houses with startlabel A | B40: 2176 Terraced houses - startlabel A | C40: 1 | D40: 2035 | F40: 0.3625 | G40: M terraced houses | I40: 0.3625 | J40: M terraced houses
A41: Energy in terraced houses with startlabel A | B41: 2397 Terraced houses - startlabel A retrofitted to A+ | C41: 1 | D41: 2035 | F41: 0 | G41: M terraced houses | I41: 0 | J41: M terraced houses
A42: Energy in terraced houses with startlabel A+ | B42: 2171 Terraced houses - startlabel A+ | C42: 1 | D42: 2035 | E42: 0.452 | F42: 0.452 | G42: M terraced houses | H42: 0.0339 | I42: 0.452 | J42: M terraced houses
A43: Energy in terraced houses with startlabel DC and B | B43: 2170 Terraced houses - startlabel B or DC retrofitted to B | C43: 1 | D43: 2035 | E43: 1.1347 | F43: 1.1347 | G43: M terraced houses | H43: 0.0851 | I43: 1.1344 | J43: M terraced houses
A44: Energy in terraced houses with startlabel DC and B | B44: 2175 Terraced houses - startlabel DC | C44: 1 | D44: 2035 | F44: 0.3193 | G44: M terraced houses | I44: 0.3196 | J44: M terraced houses
A45: Energy in terraced houses with startlabel DC and B | B45: 2399 Terraced houses - startlabel DC/B retrofitted to A | C45: 1 | D45: 2035 | F45: 0 | G45: M terraced houses | I45: 0 | J45: M terraced houses
A46: Energy in terraced houses with startlabel GFE | B46: 2404 Terraced houses - startlabel GFE retrofitted to DC | C46: 1 | D46: 2035 | F46: 0.2564 | G46: M terraced houses | I46: 0.2564 | J46: M terraced houses
A47: Energy in terraced houses with startlabel GFE | B47: 2405 Terraced houses - startlabel GFE retrofitted to B | C47: 1 | D47: 2035 | F47: 0 | G47: M terraced houses | I47: 0 | J47: M terraced houses
A48: LULUCF | B48: 2157 REF LULUCF CO2 | C48: 1 | D48: 2035 | E48: 10 | G48: Mton | H48: 10 | J48: Mton
A49: apartments | B49: 2172 Apartments - startlabel B or DC retrofitted to B | C49: 1 | D49: 2035 | F49: 1.2454 | G49: M apartments | I49: 1.2451 | J49: M apartments
A50: apartments | B50: 2178 Apartments - startlabel DC | C50: 1 | D50: 2035 | F50: 0.3249 | G50: M apartments | I50: 0.3252 | J50: M apartments
A51: apartments | B51: 2179 Apartments - startlabel DC/B retrofitted to A | C51: 1 | D51: 2035 | G51: M apartments | I51: 0 | J51: M apartments
A52: apartments | B52: 2180 Apartments - startlabel A/A+ | C52: 1 | D52: 2035 | F52: 0.8384 | G52: M apartments | I52: 0.8384 | J52: M apartments
...

Sheet Energy balance options
A2: Energy balance of all options and all energy carriers. Unit: PJ, but Mton CO2 for CO2flow. '+' is input, '-' is output.
P3: NG use [PJ] | S3: Correction chemie | V3: Corrected NG use [PJ]
B4: Identifier | C4: Sector | D4: Energy Input(+)/Ouput(-) [PJ]
A5: Option | B5: Energy carrier | F5: Production | G5: Consumption | O5: Sector
A6: 913 Mono manure AD Green gas | B6: Aardgas | C6: Landbouw | D6: -14.999909 | F6: =IF(D6<0,D6,"") -> -14.999909 | G6: =IF(D6>0,D6,"") | O6: Landbouw | P6: =SUMIFS($D$7:$D$4000,$C$7:$C$4000,$O6,$B$7:$B$4000,"aardgas") -> 20.002627 | S6: 1394 REF NonEn Chemie ebalans | T6: =SUMIFS($D$7:$D$4000,$A$7:$A$4000,$S6,$B$7:$B$4000,"Aardgas") -> 0 | V6: =P6 -> 20.002627
A7: 913 Mono manure AD Green gas | B7: Biogas | C7: Landbouw | F7: =IF(D7<0,D7,"") | G7: =IF(D7>0,D7,"") | O7: Overige landbouw | P7: =SUMIFS($D$7:$D$4000,$C$7:$C$4000,$O7,$B$7:$B$4000,"aardgas") -> 0 | S7: 1780 REF non energetisch en ovg omz chemie | T7: =SUMIFS($D$7:$D$4000,$A$7:$A$4000,$S7,$B$7:$B$4000,"Aardgas") -> 5.569212 | V7: =P7 -> 0
A8: 913 Mono manure AD Green gas | B8: E-inhoud mest | C8: Landbouw | D8: 14.999909 | F8: =IF(D8<0,D8,"") | G8: =IF(D8>0,D8,"") -> 14.999909 | O8: Huishoudens | P8: =SUMIFS($D$7:$D$4000,$C$7:$C$4000,$O8,$B$7:$B$4000,"aardgas") -> 224.8005 | S8: 2161 Non energetisch en ovg omz chemie - bio | T8: =SUMIFS($D$7:$D$4000,$A$7:$A$4000,$S8,$B$7:$B$4000,"Aardgas") -> 0 | V8: =P8 -> 224.8005
A9: 985 Lignocellulosic ethanol production | B9: Bio-ethanol | C9: Raffinaderijen | D9: -3.3420919e-06 | F9: =IF(D9<0,D9,"") -> -3.3420919e-06 | G9: =IF(D9>0,D9,"") | O9: HDO | P9: =SUMIFS($D$7:$D$4000,$C$7:$C$4000,$O9,$B$7:$B$4000,"aardgas") -> 65.719411 | S9: 2356 REF methanol from NG | T9: =SUMIFS($D$7:$D$4000,$A$7:$A$4000,$S9,$B$7:$B$4000,"Aardgas") -> 12.749463 | V9: =P9 -> 65.719411
A10: 985 Lignocellulosic ethanol production | B10: Biomassa (hout) | C10: Raffinaderijen | D10: 9.099403e-06 | F10: =IF(D10<0,D10,"") | G10: =IF(D10>0,D10,"") -> 9.099403e-06 | O10: Bunkers | P10: =SUMIFS($D$7:$D$4000,$C$7:$C$4000,$O10,$B$7:$B$4000,"aardgas") -> 0 | S10: 2379 Non energetisch en ovg omz chemie - external heat | T10: =SUMIFS($D$7:$D$4000,$A$7:$A$4000,$S10,$B$7:$B$4000,"Aardgas") -> 0 | V10: =P10 -> 0
A11: 985 Lignocellulosic ethanol production | B11: Elektriciteit | C11: Raffinaderijen | D11: -3.9679289e-07 | F11: =IF(D11<0,D11,"") -> -3.9679289e-07 | G11: =IF(D11>0,D11,"") | O11: Elektriciteitsopwekking | P11: =SUMIFS($D$7:$D$4000,$C$7:$C$4000,$O11,$B$7:$B$4000,"aardgas") -> 96.549437 | V11: =P11 -> 96.549437
A12: 986 Ethanol uit biomassa (starch) 2011 | B12: Bio-ethanol | C12: Raffinaderijen | F12: =IF(D12<0,D12,"") | G12: =IF(D12>0,D12,"") | O12: Warmteopwekking (centraal) | P12: =SUMIFS($D$7:$D$4000,$C$7:$C$4000,$O12,$B$7:$B$4000,"aardgas") -> 19.264158 | V12: =P12 -> 19.264158
A13: 986 Ethanol uit biomassa (starch) 2011 | B13: Biomassa (zetmeel) | C13: Raffinaderijen | F13: =IF(D13<0,D13,"") | G13: =IF(D13>0,D13,"") | O13: Basic metal non-ferro | P13: =SUMIFS($D$7:$D$4000,$C$7:$C$4000,$O13,$B$7:$B$4000,"aardgas") -> 0.62987196 | V13: =P13 -> 0.62987196
A14: 987 Ethanol uit biomassa (suiker) 2011 | B14: Bio-ethanol | C14: Raffinaderijen | D14: -3.9487323e-06 | F14: =IF(D14<0,D14,"") -> -3.9487323e-06 | G14: =IF(D14>0,D14,"") | O14: Basismetaal ferro | P14: =SUMIFS($D$7:$D$4000,$C$7:$C$4000,$O14,$B$7:$B$4000,"aardgas") -> 32.192778 | V14: =P14 -> 32.192778
A15: 987 Ethanol uit biomassa (suiker) 2011 | B15: Biomassa (suikers) | C15: Raffinaderijen | D15: 8.833853e-06 | F15: =IF(D15<0,D15,"") | G15: =IF(D15>0,D15,"") -> 8.833853e-06 | O15: Chemie | P15: =SUMIFS($D$7:$D$4000,$C$7:$C$4000,$O15,$B$7:$B$4000,"aardgas") -> 26.77583 | V15: =P15-SUM(T6:T10) -> 8.4571551
A16: 993 H2 uit olievergassing met CCS 2011 | B16: CO2Flow | C16: H2 voorziening | F16: =IF(D16<0,D16,"") | G16: =IF(D16>0,D16,"") | O16: Food and Beverage Industry | P16: =SUMIFS($D$7:$D$4000,$C$7:$C$4000,$O16,$B$7:$B$4000,"aardgas") -> 7.1722837 | V16: =P16 -> 7.1722837
A17: 993 H2 uit olievergassing met CCS 2011 | B17: Elektriciteit | C17: H2 voorziening | F17: =IF(D17<0,D17,"") | G17: =IF(D17>0,D17,"") | O17: Gasvoorziening | P17: =SUMIFS($D$7:$D$4000,$C$7:$C$4000,$O17,$B$7:$B$4000,"aardgas") -> 5.6393808e-05 | V17: =P17 -> 5.6393808e-05
A18: 993 H2 uit olievergassing met CCS 2011 | B18: Olie | C18: H2 voorziening | F18: =IF(D18<0,D18,"") | G18: =IF(D18>0,D18,"") | O18: H2 voorziening | P18: =SUMIFS($D$7:$D$4000,$C$7:$C$4000,$O18,$B$7:$B$4000,"aardgas") -> 78.453321 | V18: =P18 -> 78.453321
A19: 993 H2 uit olievergassing met CCS 2011 | B19: Waterstof | C19: H2 voorziening | F19: =IF(D19<0,D19,"") | G19: =IF(D19>0,D19,"") | O19: Industrie | P19: =SUMIFS($D$7:$D$4000,$C$7:$C$4000,$O19,$B$7:$B$4000,"aardgas") -> 35.642607 | V19: =P19 -> 35.642607
A20: 996 H2 uit biomassavergassing CCS 2011 | B20: Biomassa (hout) | C20: H2 voorziening | F20: =IF(D20<0,D20,"") | G20: =IF(D20>0,D20,"") | O20: Kunstmestindustrie | P20: =SUMIFS($D$7:$D$4000,$C$7:$C$4000,$O20,$B$7:$B$4000,"aardgas") -> 59.829772 | V20: =P20 -> 59.829772
A21: 996 H2 uit biomassavergassing CCS 2011 | B21: CO2Flow | C21: H2 voorziening | F21: =IF(D21<0,D21,"") | G21: =IF(D21>0,D21,"") | O21: Raffinaderijen | P21: =SUMIFS($D$7:$D$4000,$C$7:$C$4000,$O21,$B$7:$B$4000,"aardgas") -> 11.052244 | V21: =P21 -> 11.052244
A22: 996 H2 uit biomassavergassing CCS 2011 | B22: Elektriciteit | C22: H2 voorziening | F22: =IF(D22<0,D22,"") | G22: =IF(D22>0,D22,"") | O22: Waste | P22: =SUMIFS($D$7:$D$4000,$C$7:$C$4000,$O22,$B$7:$B$4000,"aardgas") -> 0.0036721374 | V22: =P22 -> 0.0036721374
A23: 996 H2 uit biomassavergassing CCS 2011 | B23: Waterstof | C23: H2 voorziening | F23: =IF(D23<0,D23,"") | G23: =IF(D23>0,D23,"") | O23: Verkeer | P23: =SUMIFS($D$7:$D$4000,$C$7:$C$4000,$O23,$B$7:$B$4000,"aardgas") -> 2.4315968 | V23: =P23 -> 2.4315968
A24: 998 H2 uit biomassavergassing 2011 | B24: Biomassa (hout) | C24: H2 voorziening | D24: 1.8932093e-05 | F24: =IF(D24<0,D24,"") | G24: =IF(D24>0,D24,"") -> 1.8932093e-05 | O24: MWT | P24: =SUMIFS($D$7:$D$4000,$C$7:$C$4000,$O24,$B$7:$B$4000,"aardgas") -> 0 | V24: =P24 -> 0
A25: 998 H2 uit biomassavergassing 2011 | B25: Elektriciteit | C25: H2 voorziening | D25: 1.1576299e-06 | F25: =IF(D25<0,D25,"") | G25: =IF(D25>0,D25,"") -> 1.1576299e-06
A26: 998 H2 uit biomassavergassing 2011 | B26: Waterstof | C26: H2 voorziening | D26: -1.3819046e-05 | F26: =IF(D26<0,D26,"") -> -1.3819046e-05 | G26: =IF(D26>0,D26,"")
A27: 999 H2 uit SMR met CCS 2011 | B27: Aardgas | C27: H2 voorziening | F27: =IF(D27<0,D27,"") | G27: =IF(D27>0,D27,"")
A28: 999 H2 uit SMR met CCS 2011 | B28: CO2Flow | C28: H2 voorziening | F28: =IF(D28<0,D28,"") | G28: =IF(D28>0,D28,"")
A29: 999 H2 uit SMR met CCS 2011 | B29: Waterstof | C29: H2 voorziening | F29: =IF(D29<0,D29,"") | G29: =IF(D29>0,D29,"")
A30: 1003 Micro-WKK Brandstofcel 2011 (WB nieuwbouw) | B30: Elektriciteit | C30: Huishoudens | D30: -2.0253418e-07 | F30: =IF(D30<0,D30,"") -> -2.0253418e-07 | G30: =IF(D30>0,D30,"")
A31: 1003 Micro-WKK Brandstofcel 2011 (WB nieuwbouw) | B31: Warmte | C31: Huishoudens | D31: -3.024147e-07 | F31: =IF(D31<0,D31,"") -> -3.024147e-07 | G31: =IF(D31>0,D31,"")
A32: 1003 Micro-WKK Brandstofcel 2011 (WB nieuwbouw) | B32: Waterstof | C32: Huishoudens | D32: 4.8668062e-07 | F32: =IF(D32<0,D32,"") | G32: =IF(D32>0,D32,"") -> 4.8668062e-07
A33: 1010 Micro-WKK Brandstofcel 2011 (WB bestaande bouw) | B33: Elektriciteit | C33: Huishoudens | F33: =IF(D33<0,D33,"") | G33: =IF(D33>0,D33,"")
A34: 1010 Micro-WKK Brandstofcel 2011 (WB bestaande bouw) | B34: Warmte | C34: Huishoudens | F34: =IF(D34<0,D34,"") | G34: =IF(D34>0,D34,"")
A35: 1010 Micro-WKK Brandstofcel 2011 (WB bestaande bouw) | B35: Waterstof | C35: Huishoudens | F35: =IF(D35<0,D35,"") | G35: =IF(D35>0,D35,"")
A36: 1012 Solar-PV Residential | B36: Elektriciteit | C36: Huishoudens | D36: -30.326279 | F36: =IF(D36<0,D36,"") -> -30.326279 | G36: =IF(D36>0,D36,"")
A37: 1012 Solar-PV Residential | B37: Zon | C37: Huishoudens | D37: 30.326279 | F37: =IF(D37<0,D37,"") | G37: =IF(D37>0,D37,"") -> 30.326279
A38: 1013 Biomassavergassing met CCS 7000u 2011 | B38: Biomassa (hout) | C38: Elektriciteitsopwekking | D38: 2.0531186e-05 | F38: =IF(D38<0,D38,"") | G38: =IF(D38>0,D38,"") -> 2.0531186e-05
A39: 1013 Biomassavergassing met CCS 7000u 2011 | B39: CO2Flow | C39: Elektriciteitsopwekking | D39: -2.025198e-06 | F39: =IF(D39<0,D39,"") -> -2.025198e-06 | G39: =IF(D39>0,D39,"")
A40: 1013 Biomassavergassing met CCS 7000u 2011 | B40: Elektriciteit | C40: Elektriciteitsopwekking | D40: -1.2125396e-06 | F40: =IF(D40<0,D40,"") -> -1.2125396e-06 | G40: =IF(D40>0,D40,"")
A41: 1016 ATR with CC | B41: Aardgas | C41: H2 voorziening | D41: 13.154776 | F41: =IF(D41<0,D41,"") | G41: =IF(D41>0,D41,"") -> 13.154776
...

Sheet Prod-Cons 2nd energy carriers
A2: Production and consumption of secondary energy carriers. '+' is input, '-' is output. Figures are including infrastructure losses
B4: PJ | D4: TWh
A5: Energy carrier | B5: Production | C5: Consumption | D5: Production | E5: Consumption
A6: Elektriciteit | B6: =SUMIF('Energy balance options'!$B$6:$B$3000,'Prod-Cons 2nd energy carriers'!$A6,'Energy balance options'!F$6:F$3000) -> -568.68438 | C6: =SUMIF('Energy balance options'!$B$6:$B$3000,'Prod-Cons 2nd energy carriers'!$A6,'Energy balance options'!G$6:G$3000) -> 568.6844 | D6: =B6/3.6 -> -157.96788 | E6: =C6/3.6 -> 157.96789
A7: warmte | B7: =SUMIF('Energy balance options'!$B$6:$B$3000,'Prod-Cons 2nd energy carriers'!$A7,'Energy balance options'!F$6:F$3000) -> -505.21682 | C7: =SUMIF('Energy balance options'!$B$6:$B$3000,'Prod-Cons 2nd energy carriers'!$A7,'Energy balance options'!G$6:G$3000) -> 505.21682 | D7: =B7/3.6 -> -140.33801 | E7: =C7/3.6 -> 140.338
A8: Waterstof | B8: =SUMIF('Energy balance options'!$B$6:$B$3000,'Prod-Cons 2nd energy carriers'!$A8,'Energy balance options'!F$6:F$3000) -> -72.229946 | C8: =SUMIF('Energy balance options'!$B$6:$B$3000,'Prod-Cons 2nd energy carriers'!$A8,'Energy balance options'!G$6:G$3000) -> 72.229941 | D8: =B8/3.6 -> -20.063874 | E8: =C8/3.6 -> 20.063872
A9: Aardgas | B9: =SUMIF('Energy balance options'!$B$6:$B$3000,'Prod-Cons 2nd energy carriers'!$A9,'Energy balance options'!F$6:F$3000) -> -15.141348 | C9: =SUMIF('Energy balance options'!$B$6:$B$3000,'Prod-Cons 2nd energy carriers'!$A9,'Energy balance options'!G$6:G$3000) -> 680.66161 | D9: =B9/3.6 -> -4.2059301 | E9: =C9/3.6 -> 189.07267

Sheet Refinery sector
I1: Raffinaderijen
A4: Energiedrager | B4: Production | C4: Consumption | D4: Net effect | F4: Aggregation type | H4: Aggregation net consumption [PJ]
A5: Aardgas | B5: =SUMIFS('Energy balance options'!F$6:F$3000,'Energy balance options'!$B$6:$B$3000,'Refinery sector'!$A5,'Energy balance options'!$C$6:$C$3000,'Refinery sector'!$I$1) -> 0 | C5: =SUMIFS('Energy balance options'!G$6:G$3000,'Energy balance options'!$B$6:$B$3000,'Refinery sector'!$A5,'Energy balance options'!$C$6:$C$3000,'Refinery sector'!$I$1) -> 11.052244 | D5: =B5+C5 -> 11.052244 | F5: Natural gas | H5: Natural gas | I5: =SUMIF($F$5:$F$67,H5,$D$5:$D$67) -> 11.052244
A6: Ammonia | B6: =SUMIFS('Energy balance options'!F$6:F$3000,'Energy balance options'!$B$6:$B$3000,'Refinery sector'!$A6,'Energy balance options'!$C$6:$C$3000,'Refinery sector'!$I$1) -> 0 | C6: =SUMIFS('Energy balance options'!G$6:G$3000,'Energy balance options'!$B$6:$B$3000,'Refinery sector'!$A6,'Energy balance options'!$C$6:$C$3000,'Refinery sector'!$I$1) -> 0 | D6: =B6+C6 -> 0 | F6: Ammonia | H6: Ammonia | I6: =SUMIF($F$5:$F$67,H6,$D$5:$D$67) -> 0
A7: Ammonia export | B7: =SUMIFS('Energy balance options'!F$6:F$3000,'Energy balance options'!$B$6:$B$3000,'Refinery sector'!$A7,'Energy balance options'!$C$6:$C$3000,'Refinery sector'!$I$1) -> 0 | C7: =SUMIFS('Energy balance options'!G$6:G$3000,'Energy balance options'!$B$6:$B$3000,'Refinery sector'!$A7,'Energy balance options'!$C$6:$C$3000,'Refinery sector'!$I$1) -> 0 | D7: =B7+C7 -> 0 | F7: Ammonia | H7: Electricity | I7: =SUMIF($F$5:$F$67,H7,$D$5:$D$67) -> 8.375525
A8: Ammonia import | B8: =SUMIFS('Energy balance options'!F$6:F$3000,'Energy balance options'!$B$6:$B$3000,'Refinery sector'!$A8,'Energy balance options'!$C$6:$C$3000,'Refinery sector'!$I$1) -> 0 | C8: =SUMIFS('Energy balance options'!G$6:G$3000,'Energy balance options'!$B$6:$B$3000,'Refinery sector'!$A8,'Energy balance options'!$C$6:$C$3000,'Refinery sector'!$I$1) -> 0 | D8: =B8+C8 -> 0 | F8: Ammonia | H8: Heat | I8: =SUMIF($F$5:$F$67,H8,$D$5:$D$67) -> -2.1779425
A9: Aromatics | B9: =SUMIFS('Energy balance options'!F$6:F$3000,'Energy balance options'!$B$6:$B$3000,'Refinery sector'!$A9,'Energy balance options'!$C$6:$C$3000,'Refinery sector'!$I$1) -> -85.275114 | C9: =SUMIFS('Energy balance options'!G$6:G$3000,'Energy balance options'!$B$6:$B$3000,'Refinery sector'!$A9,'Energy balance options'!$C$6:$C$3000,'Refinery sector'!$I$1) -> 0 | D9: =B9+C9 -> -85.275114 | F9: Fossil feedstock | H9: Hydrogen | I9: =SUMIF($F$5:$F$67,H9,$D$5:$D$67) -> 60.954884
A10: Benzine | B10: =SUMIFS('Energy balance options'!F$6:F$3000,'Energy balance options'!$B$6:$B$3000,'Refinery sector'!$A10,'Energy balance options'!$C$6:$C$3000,'Refinery sector'!$I$1) -> -102.03557 | C10: =SUMIFS('Energy balance options'!G$6:G$3000,'Energy balance options'!$B$6:$B$3000,'Refinery sector'!$A10,'Energy balance options'!$C$6:$C$3000,'Refinery sector'!$I$1) -> 0 | D10: =B10+C10 -> -102.03557 | F10: Fossil fuel | H10: Waste gasses | I10: =SUMIF($F$5:$F$67,H10,$D$5:$D$67) -> -54.012021
A11: Bio-aromatics | B11: =SUMIFS('Energy balance options'!F$6:F$3000,'Energy balance options'!$B$6:$B$3000,'Refinery sector'!$A11,'Energy balance options'!$C$6:$C$3000,'Refinery sector'!$I$1) -> 0 | C11: =SUMIFS('Energy balance options'!G$6:G$3000,'Energy balance options'!$B$6:$B$3000,'Refinery sector'!$A11,'Energy balance options'!$C$6:$C$3000,'Refinery sector'!$I$1) -> 0 | D11: =B11+C11 -> 0 | F11: Bio feedstock | H11: Bio waste gasses | I11: =SUMIF($F$5:$F$67,H11,$D$5:$D$67) -> -0.40737171
A12: Biobenzine | B12: =SUMIFS('Energy balance options'!F$6:F$3000,'Energy balance options'!$B$6:$B$3000,'Refinery sector'!$A12,'Energy balance options'!$C$6:$C$3000,'Refinery sector'!$I$1) -> -0.00020763998 | C12: =SUMIFS('Energy balance options'!G$6:G$3000,'Energy balance options'!$B$6:$B$3000,'Refinery sector'!$A12,'Energy balance options'!$C$6:$C$3000,'Refinery sector'!$I$1) -> 0 | D12: =B12+C12 -> -0.00020763998 | F12: Biofuel | H12: Synthetic waste gasses | I12: =SUMIF($F$5:$F$67,H12,$D$5:$D$67) -> 2.4116916e-05
A13: Biobrandstoffen | B13: =SUMIFS('Energy balance options'!F$6:F$3000,'Energy balance options'!$B$6:$B$3000,'Refinery sector'!$A13,'Energy balance options'!$C$6:$C$3000,'Refinery sector'!$I$1) -> 0 | C13: =SUMIFS('Energy balance options'!G$6:G$3000,'Energy balance options'!$B$6:$B$3000,'Refinery sector'!$A13,'Energy balance options'!$C$6:$C$3000,'Refinery sector'!$I$1) -> 0 | D13: =B13+C13 -> 0 | F13: Biofuel | H13: Other oil products | I13: =SUMIF($F$5:$F$67,H13,$D$5:$D$67) -> -54.761801
A14: Biodiesel | B14: =SUMIFS('Energy balance options'!F$6:F$3000,'Energy balance options'!$B$6:$B$3000,'Refinery sector'!$A14,'Energy balance options'!$C$6:$C$3000,'Refinery sector'!$I$1) -> -16.339378 | C14: =SUMIFS('Energy balance options'!G$6:G$3000,'Energy balance options'!$B$6:$B$3000,'Refinery sector'!$A14,'Energy balance options'!$C$6:$C$3000,'Refinery sector'!$I$1) -> 0 | D14: =B14+C14 -> -16.339378 | F14: Biofuel | H14: Other bio oil products | I14: =SUMIF($F$5:$F$67,H14,$D$5:$D$67) -> 0
A15: Bio-DME | B15: =SUMIFS('Energy balance options'!F$6:F$3000,'Energy balance options'!$B$6:$B$3000,'Refinery sector'!$A15,'Energy balance options'!$C$6:$C$3000,'Refinery sector'!$I$1) -> -3.2887367e-05 | C15: =SUMIFS('Energy balance options'!G$6:G$3000,'Energy balance options'!$B$6:$B$3000,'Refinery sector'!$A15,'Energy balance options'!$C$6:$C$3000,'Refinery sector'!$I$1) -> 0 | D15: =B15+C15 -> -3.2887367e-05 | F15: Biofuel | H15: Other synthetic oil products | I15: =SUMIF($F$5:$F$67,H15,$D$5:$D$67) -> 0
A16: Bio-ethanol | B16: =SUMIFS('Energy balance options'!F$6:F$3000,'Energy balance options'!$B$6:$B$3000,'Refinery sector'!$A16,'Energy balance options'!$C$6:$C$3000,'Refinery sector'!$I$1) -> -0.00018765594 | C16: =SUMIFS('Energy balance options'!G$6:G$3000,'Energy balance options'!$B$6:$B$3000,'Refinery sector'!$A16,'Energy balance options'!$C$6:$C$3000,'Refinery sector'!$I$1) -> 2.9101907e-05 | D16: =B16+C16 -> -0.00015855403 | F16: Biofuel | H16: Plastic Pyrolysis Oil | I16: =SUMIF($F$5:$F$67,H16,$D$5:$D$67) -> 0
... A24: Biomassa (hout) | B24: =SUMIFS('Energy balance options'!F$6:F$3000,'Energy balance options'!$B$6:$B$3000,'Refinery sector'!$A24,'Energy balance options'!$C$6:$C$3000,'Refinery sector'!$I$1) -> -64.86006 | C24: =SUMIFS('Energy balance options'!G$6:G$3000,'Energy balance options'!$B$6:$B$3000,'Refinery sector'!$A24,'Energy balance options'!$C$6:$C$3000,'Refinery sector'!$I$1) -> 14.587255 | D24: =B24+C24 -> -50.272805 | F24: Biomass | H24: Synthetic feedstock | I24: =SUMIF($F$5:$F$67,H24,$D$5:$D$67) -> -1.2102414e-05
A25: Biomassa (natte stromen) | B25: =SUMIFS('Energy balance options'!F$6:F$3000,'Energy balance options'!$B$6:$B$3000,'Refinery sector'!$A25,'Energy balance options'!$C$6:$C$3000,'Refinery sector'!$I$1) -> 0 | C25: =SUMIFS('Energy balance options'!G$6:G$3000,'Energy balance options'!$B$6:$B$3000,'Refinery sector'!$A25,'Energy balance options'!$C$6:$C$3000,'Refinery sector'!$I$1) -> 0 | D25: =B25+C25 -> 0 | F25: Biomass
A26: Biomassa (suikers) | B26: =SUMIFS('Energy balance options'!F$6:F$3000,'Energy balance options'!$B$6:$B$3000,'Refinery sector'!$A26,'Energy balance options'!$C$6:$C$3000,'Refinery sector'!$I$1) -> 0 | C26: =SUMIFS('Energy balance options'!G$6:G$3000,'Energy balance options'!$B$6:$B$3000,'Refinery sector'!$A26,'Energy balance options'!$C$6:$C$3000,'Refinery sector'!$I$1) -> 8.833853e-06 | D26: =B26+C26 -> 8.833853e-06 | F26: Biomass | H26: Total net | I26: =SUM(I5:I24) -> 140.52776
A27: Biomassa (UCO buitenland) | B27: =SUMIFS('Energy balance options'!F$6:F$3000,'Energy balance options'!$B$6:$B$3000,'Refinery sector'!$A27,'Energy balance options'!$C$6:$C$3000,'Refinery sector'!$I$1) -> 0 | C27: =SUMIFS('Energy balance options'!G$6:G$3000,'Energy balance options'!$B$6:$B$3000,'Refinery sector'!$A27,'Energy balance options'!$C$6:$C$3000,'Refinery sector'!$I$1) -> 23.5048 | D27: =B27+C27 -> 23.5048 | F27: Biomass
A28: Biomethanol | B28: =SUMIFS('Energy balance options'!F$6:F$3000,'Energy balance options'!$B$6:$B$3000,'Refinery sector'!$A28,'Energy balance options'!$C$6:$C$3000,'Refinery sector'!$I$1) -> 0 | C28: =SUMIFS('Energy balance options'!G$6:G$3000,'Energy balance options'!$B$6:$B$3000,'Refinery sector'!$A28,'Energy balance options'!$C$6:$C$3000,'Refinery sector'!$I$1) -> 3.3150389e-05 | D28: =B28+C28 -> 3.3150389e-05 | F28: Bio waste gasses
A29: Bio-methanol for shipping | B29: =SUMIFS('Energy balance options'!F$6:F$3000,'Energy balance options'!$B$6:$B$3000,'Refinery sector'!$A29,'Energy balance options'!$C$6:$C$3000,'Refinery sector'!$I$1) -> 0 | C29: =SUMIFS('Energy balance options'!G$6:G$3000,'Energy balance options'!$B$6:$B$3000,'Refinery sector'!$A29,'Energy balance options'!$C$6:$C$3000,'Refinery sector'!$I$1) -> 0 | D29: =B29+C29 -> 0 | F29: Biofuel | H29: CO2 captured | I29: Mton
A30: Bionaphta | B30: =SUMIFS('Energy balance options'!F$6:F$3000,'Energy balance options'!$B$6:$B$3000,'Refinery sector'!$A30,'Energy balance options'!$C$6:$C$3000,'Refinery sector'!$I$1) -> -3.546793 | C30: =SUMIFS('Energy balance options'!G$6:G$3000,'Energy balance options'!$B$6:$B$3000,'Refinery sector'!$A30,'Energy balance options'!$C$6:$C$3000,'Refinery sector'!$I$1) -> 0 | D30: =B30+C30 -> -3.546793 | F30: Bio feedstock | H30: CO2flow | I30: =-SUMIF('Energy balance options'!$B$6:$B$3000,H30,'Energy balance options'!F$6:F$3000) -> 10.62991
A31: Bio-restgassen | B31: =SUMIFS('Energy balance options'!F$6:F$3000,'Energy balance options'!$B$6:$B$3000,'Refinery sector'!$A31,'Energy balance options'!$C$6:$C$3000,'Refinery sector'!$I$1) -> -0.61819416 | C31: =SUMIFS('Energy balance options'!G$6:G$3000,'Energy balance options'!$B$6:$B$3000,'Refinery sector'!$A31,'Energy balance options'!$C$6:$C$3000,'Refinery sector'!$I$1) -> 0.2107893 | D31: =B31+C31 -> -0.40740486 | F31: Bio waste gasses
A32: Diesel | B32: =SUMIFS('Energy balance options'!F$6:F$3000,'Energy balance options'!$B$6:$B$3000,'Refinery sector'!$A32,'Energy balance options'!$C$6:$C$3000,'Refinery sector'!$I$1) -> -526.50937 | C32: =SUMIFS('Energy balance options'!G$6:G$3000,'Energy balance options'!$B$6:$B$3000,'Refinery sector'!$A32,'Energy balance options'!$C$6:$C$3000,'Refinery sector'!$I$1) -> 0 | D32: =B32+C32 -> -526.50937 | F32: Fossil fuel
A33: Elektriciteit | B33: =SUMIFS('Energy balance options'!F$6:F$3000,'Energy balance options'!$B$6:$B$3000,'Refinery sector'!$A33,'Energy balance options'!$C$6:$C$3000,'Refinery sector'!$I$1) -> -4.3811504 | C33: =SUMIFS('Energy balance options'!G$6:G$3000,'Energy balance options'!$B$6:$B$3000,'Refinery sector'!$A33,'Energy balance options'!$C$6:$C$3000,'Refinery sector'!$I$1) -> 12.756675 | D33: =B33+C33 -> 8.375525 | F33: Electricity
A34: Heat100to200 | B34: =SUMIFS('Energy balance options'!F$6:F$3000,'Energy balance options'!$B$6:$B$3000,'Refinery sector'!$A34,'Energy balance options'!$C$6:$C$3000,'Refinery sector'!$I$1) -> -1.2476184 | C34: =SUMIFS('Energy balance options'!G$6:G$3000,'Energy balance options'!$B$6:$B$3000,'Refinery sector'!$A34,'Energy balance options'!$C$6:$C$3000,'Refinery sector'!$I$1) -> 1.247604 | D34: =B34+C34 -> -1.434721e-05 | F34: Heat
A35: Heat200to400 | B35: =SUMIFS('Energy balance options'!F$6:F$3000,'Energy balance options'!$B$6:$B$3000,'Refinery sector'!$A35,'Energy balance options'!$C$6:$C$3000,'Refinery sector'!$I$1) -> -79.037463 | C35: =SUMIFS('Energy balance options'!G$6:G$3000,'Energy balance options'!$B$6:$B$3000,'Refinery sector'!$A35,'Energy balance options'!$C$6:$C$3000,'Refinery sector'!$I$1) -> 79.037416 | D35: =B35+C35 -> -4.7327278e-05 | F35: Heat
A36: HeatDir200to400 | B36: =SUMIFS('Energy balance options'!F$6:F$3000,'Energy balance options'!$B$6:$B$3000,'Refinery sector'!$A36,'Energy balance options'!$C$6:$C$3000,'Refinery sector'!$I$1) -> 0 | C36: =SUMIFS('Energy balance options'!G$6:G$3000,'Energy balance options'!$B$6:$B$3000,'Refinery sector'!$A36,'Energy balance options'!$C$6:$C$3000,'Refinery sector'!$I$1) -> 0 | D36: =B36+C36 -> 0 | F36: Heat
A37: HeatHT400 | B37: =SUMIFS('Energy balance options'!F$6:F$3000,'Energy balance options'!$B$6:$B$3000,'Refinery sector'!$A37,'Energy balance options'!$C$6:$C$3000,'Refinery sector'!$I$1) -> 0 | C37: =SUMIFS('Energy balance options'!G$6:G$3000,'Energy balance options'!$B$6:$B$3000,'Refinery sector'!$A37,'Energy balance options'!$C$6:$C$3000,'Refinery sector'!$I$1) -> 0 | D37: =B37+C37 -> 0 | F37: Heat
A38: HeatLessThan200 | B38: =SUMIFS('Energy balance options'!F$6:F$3000,'Energy balance options'!$B$6:$B$3000,'Refinery sector'!$A38,'Energy balance options'!$C$6:$C$3000,'Refinery sector'!$I$1) -> 0 | C38: =SUMIFS('Energy balance options'!G$6:G$3000,'Energy balance options'!$B$6:$B$3000,'Refinery sector'!$A38,'Energy balance options'!$C$6:$C$3000,'Refinery sector'!$I$1) -> 0 | D38: =B38+C38 -> 0 | F38: Heat
A39: HeatMoreThan200 | B39: =SUMIFS('Energy balance options'!F$6:F$3000,'Energy balance options'!$B$6:$B$3000,'Refinery sector'!$A39,'Energy balance options'!$C$6:$C$3000,'Refinery sector'!$I$1) -> 0 | C39: =SUMIFS('Energy balance options'!G$6:G$3000,'Energy balance options'!$B$6:$B$3000,'Refinery sector'!$A39,'Energy balance options'!$C$6:$C$3000,'Refinery sector'!$I$1) -> 0 | D39: =B39+C39 -> 0 | F39: Heat
A40: HFO | B40: =SUMIFS('Energy balance options'!F$6:F$3000,'Energy balance options'!$B$6:$B$3000,'Refinery sector'!$A40,'Energy balance options'!$C$6:$C$3000,'Refinery sector'!$I$1) -> -243.62142 | C40: =SUMIFS('Energy balance options'!G$6:G$3000,'Energy balance options'!$B$6:$B$3000,'Refinery sector'!$A40,'Energy balance options'!$C$6:$C$3000,'Refinery sector'!$I$1) -> 0 | D40: =B40+C40 -> -243.62142 | F40: Fossil fuel
A41: Industrial Waste Heat | B41: =SUMIFS('Energy balance options'!F$6:F$3000,'Energy balance options'!$B$6:$B$3000,'Refinery sector'!$A41,'Energy balance options'!$C$6:$C$3000,'Refinery sector'!$I$1) -> -4.5320708e-05 | C41: =SUMIFS('Energy balance options'!G$6:G$3000,'Energy balance options'!$B$6:$B$3000,'Refinery sector'!$A41,'Energy balance options'!$C$6:$C$3000,'Refinery sector'!$I$1) -> 4.9352221e-05 | D41: =B41+C41 -> 4.0315123e-06 | F41: Heat
A42: Kerosine | B42: =SUMIFS('Energy balance options'!F$6:F$3000,'Energy balance options'!$B$6:$B$3000,'Refinery sector'!$A42,'Energy balance options'!$C$6:$C$3000,'Refinery sector'!$I$1) -> -236.4061 | C42: =SUMIFS('Energy balance options'!G$6:G$3000,'Energy balance options'!$B$6:$B$3000,'Refinery sector'!$A42,'Energy balance options'!$C$6:$C$3000,'Refinery sector'!$I$1) -> 0 | D42: =B42+C42 -> -236.4061 | F42: Fossil fuel
... A67: Waterstof | B67: =SUMIFS('Energy balance options'!F$6:F$3000,'Energy balance options'!$B$6:$B$3000,'Refinery sector'!$A67,'Energy balance options'!$C$6:$C$3000,'Refinery sector'!$I$1) -> 0 | C67: =SUMIFS('Energy balance options'!G$6:G$3000,'Energy balance options'!$B$6:$B$3000,'Refinery sector'!$A67,'Energy balance options'!$C$6:$C$3000,'Refinery sector'!$I$1) -> 60.954884 | D67: =B67+C67 -> 60.954884 | F67: Hydrogen

Sheet Emission per option-sector
A2: Emissions per option [Mton]. The sector the option is part of is indicated. Note there is a total, energy related and there is non-energy/correction. This non-energy/correction is used to compensate/cancel out the energy related.
B4: Identifier | C4: Sector | D4: Total [Mton] | E4: Total Energy Carrier Related [Mton] | F4: Non-energy or other correction [Mton]
A5: Option | B5: Emission Type
A6: 913 Mono manure AD Green gas | B6: Broeikasgassen | C6: Landbouw | D6: -0.98423359 | E6: -0.84899484
A7: 913 Mono manure AD Green gas | B7: CO2 | C7: Landbouw | D7: -0.84899484 | E7: -0.84899484
A8: 913 Mono manure AD Green gas | B8: CH4 | C8: Landbouw | D8: -0.19010704
A9: 913 Mono manure AD Green gas | B9: N2O | C9: Landbouw | D9: 0.054868291
A10: 1016 ATR with CC | B10: Broeikasgassen | C10: H2 voorziening | D10: 0.74456033 | E10: 0.74456033
A11: 1016 ATR with CC | B11: CO2 | C11: H2 voorziening | D11: 0.74456033 | E11: 0.74456033
A12: 1023 Ground water heat pump - Services | B12: Broeikasgassen | C12: HDO | D12: 0.011006699 | E12: 0.011006699
A13: 1023 Ground water heat pump - Services | B13: CO2 | C13: HDO | D13: 0.011006699 | E13: 0.011006699
A14: 1027 REF HR-107 - Services | B14: Broeikasgassen | C14: HDO | D14: 1.324592 | E14: 1.324592
A15: 1027 REF HR-107 - Services | B15: CO2 | C15: HDO | D15: 1.324592 | E15: 1.324592
A16: 1035 REF HR-107 - Existing - Residential | B16: Broeikasgassen | C16: Huishoudens | D16: 11.092081 | E16: 11.092081
A17: 1035 REF HR-107 - Existing - Residential | B17: CO2 | C17: Huishoudens | D17: 11.092081 | E17: 11.092081
A18: 1037 REF HR-107 - Newly built - Residential | B18: Broeikasgassen | C18: Huishoudens | D18: 1.6310842 | E18: 1.6310842
A19: 1037 REF HR-107 - Newly built - Residential | B19: CO2 | C19: Huishoudens | D19: 1.6310842 | E19: 1.6310842
A20: 1043 REF H2 uit SMR 2011 | B20: Broeikasgassen | C20: H2 voorziening | D20: 4.6549118e-06 | E20: 4.6549118e-06
A21: 1043 REF H2 uit SMR 2011 | B21: CO2 | C21: H2 voorziening | D21: 4.6549118e-06 | E21: 4.6549118e-06
... A63: 1248 REF WKK gas Landbouw ebalans | B63: CO2 | C63: Landbouw | D63: 1.2040394e-06 | E63: 1.2040394e-06
A64: 1248 REF WKK gas Landbouw ebalans | B64: CH4 | C64: Landbouw | D64: 2.4495023e-07
A65: 1270 CAES ontlader | B65: Broeikasgassen | C65: Elektriciteitsopwekking | D65: 2.0788978e-06 | E65: 2.0788978e-06
A66: 1270 CAES ontlader | B66: CO2 | C66: Elektriciteitsopwekking | D66: 2.0788978e-06 | E66: 2.0788978e-06
A67: 1273 REF diesel | B67: Broeikasgassen | C67: Verkeer | D67: 0.00017487865 | E67: 0.00017487865
A68: 1273 REF diesel | B68: CO2 | C68: Verkeer | D68: 0.00017487865 | E68: 0.00017487865
A69: 1274 REF benzine | B69: Broeikasgassen | C69: Verkeer | D69: 1.606556 | E69: 1.606556
A70: 1274 REF benzine | B70: CO2 | C70: Verkeer | D70: 1.606556 | E70: 1.606556
A71: 1284 REF OvOmz raffinaderijen ebalans | B71: Broeikasgassen | C71: Raffinaderijen | D71: 1.1352162 | E71: 1.1352162
A72: 1284 REF OvOmz raffinaderijen ebalans | B72: CO2 | C72: Raffinaderijen | D72: 1.1352162 | E72: 1.1352162
A73: 1286 REF Ketels aardgas raffinaderijen ebalans | B73: Broeikasgassen | C73: Raffinaderijen | D73: 6.6208652e-06 | E73: 6.6208652e-06
A74: 1286 REF Ketels aardgas raffinaderijen ebalans | B74: CO2 | C74: Raffinaderijen | D74: 6.6208652e-06 | E74: 6.6208652e-06
A75: 1289 REF Ketels rest raffinaderijen ebalans | B75: Broeikasgassen | C75: Raffinaderijen | D75: 2.1987094e-06 | E75: 2.1987094e-06
A76: 1289 REF Ketels rest raffinaderijen ebalans | B76: CO2 | C76: Raffinaderijen | D76: 2.1987094e-06 | E76: 2.1987094e-06
... A80: 1351 REF ICE personenauto | B80: CO2 | C80: Verkeer | D80: 6.3761278 | E80: 6.3761278
A81: 1351 REF ICE personenauto | B81: CH4 | C81: Verkeer | D81: zero
A82: 1351 REF ICE personenauto | B82: N2O | C82: Verkeer | D82: 0.11063776
A83: 1352 REF PI hybride auto | B83: Broeikasgassen | C83: Verkeer | D83: 6.8549497e-07 | E83: 6.5753303e-07
A84: 1352 REF PI hybride auto | B84: CO2 | C84: Verkeer | D84: 6.5753303e-07 | E84: 6.5753303e-07
A85: 1352 REF PI hybride auto | B85: CH4 | C85: Verkeer | D85: zero
A86: 1352 REF PI hybride auto | B86: N2O | C86: Verkeer | D86: 2.5877218e-08
...

Sheet CO2 emissions per sector
A2: CO2 emissions per sector. [Mton CO2-eq]
A4: Uncorrected, so all CO2 storage is allocated to the sector 'gasvoorziening', of which option 1512 is part | H4: Total CO2 stored | I4: =-SUMIFS('Emission per option-sector'!D6:D500,'Emission per option-sector'!A6:A500,"1512 CO2 opslag after capture",'Emission per option-sector'!B6:B500,"CO2") -> 10.500001 | L4: Corrected, so all CO2 storage is allocated to the sectors, based on the storage/capture ratio | S4: KEV2020 CO2 emissions (incl. Indirect)
R5: 2030
A6: Sector | B6: CO2 | C6: CO2, aviation | D6: CO2, shipping | E6: CO2, LULUCF | H6: Total CO2 capture | I6: Of which CCS | K6: Main Sector | L6: Sector | M6: CO2 | N6: CO2, aviation | O6: CO2, shipping | P6: CO2, LULUCF | R6: CO2 | S6: CO2, aviation | T6: CO2, shipping | U6: CO2, LULUCF
A7: Landbouw | B7: =SUMIFS('Emission per option-sector'!$D$6:$D$600,'Emission per option-sector'!$C$6:$C$600,'CO2 emissions per sector'!$A7,'Emission per option-sector'!$B$6:$B$600,B$6) -> 0.46117297 | C7: =SUMIFS('Emission per option-sector'!$D$6:$D$600,'Emission per option-sector'!$C$6:$C$600,'CO2 emissions per sector'!$A7,'Emission per option-sector'!$B$6:$B$600,C$6) -> 0 | D7: =SUMIFS('Emission per option-sector'!$D$6:$D$600,'Emission per option-sector'!$C$6:$C$600,'CO2 emissions per sector'!$A7,'Emission per option-sector'!$B$6:$B$600,D$6) -> 0 | E7: =SUMIFS('Emission per option-sector'!$D$6:$D$600,'Emission per option-sector'!$C$6:$C$600,'CO2 emissions per sector'!$A7,'Emission per option-sector'!$B$6:$B$600,E$6) -> 0 | H7: =-SUMIFS('Energy balance options'!$F$7:$F$4000,'Energy balance options'!$C$7:$C$4000,'CO2 emissions per sector'!$A7,'Energy balance options'!$B$7:$B$4000,"CO2flow") -> 0 | I7: =$I$4*H7/$H$28 -> 0 | K7: KIP agriculture | L7: Landbouw | M7: =B7-I7 -> 0.46117297 | N7: =C7 -> 0 | O7: =D7 -> 0 | P7: =E7 -> 0 | R7: 6.3079026
A8: Overige landbouw | B8: =SUMIFS('Emission per option-sector'!$D$6:$D$600,'Emission per option-sector'!$C$6:$C$600,'CO2 emissions per sector'!$A8,'Emission per option-sector'!$B$6:$B$600,B$6) -> 0 | C8: =SUMIFS('Emission per option-sector'!$D$6:$D$600,'Emission per option-sector'!$C$6:$C$600,'CO2 emissions per sector'!$A8,'Emission per option-sector'!$B$6:$B$600,C$6) -> 0 | D8: =SUMIFS('Emission per option-sector'!$D$6:$D$600,'Emission per option-sector'!$C$6:$C$600,'CO2 emissions per sector'!$A8,'Emission per option-sector'!$B$6:$B$600,D$6) -> 0 | E8: =SUMIFS('Emission per option-sector'!$D$6:$D$600,'Emission per option-sector'!$C$6:$C$600,'CO2 emissions per sector'!$A8,'Emission per option-sector'!$B$6:$B$600,E$6) -> 0 | H8: =-SUMIFS('Energy balance options'!$F$7:$F$4000,'Energy balance options'!$C$7:$C$4000,'CO2 emissions per sector'!$A8,'Energy balance options'!$B$7:$B$4000,"CO2flow") -> 0 | I8: =$I$4*H8/$H$28 -> 0 | K8: KIP agriculture | L8: Overige landbouw | M8: =B8-I8 -> 0 | N8: =C8 -> 0 | O8: =D8 -> 0 | P8: =E8 -> 0 | R8: 0
A9: Huishoudens | B9: =SUMIFS('Emission per option-sector'!$D$6:$D$600,'Emission per option-sector'!$C$6:$C$600,'CO2 emissions per sector'!$A9,'Emission per option-sector'!$B$6:$B$600,B$6) -> 13.08703 | C9: =SUMIFS('Emission per option-sector'!$D$6:$D$600,'Emission per option-sector'!$C$6:$C$600,'CO2 emissions per sector'!$A9,'Emission per option-sector'!$B$6:$B$600,C$6) -> 0 | D9: =SUMIFS('Emission per option-sector'!$D$6:$D$600,'Emission per option-sector'!$C$6:$C$600,'CO2 emissions per sector'!$A9,'Emission per option-sector'!$B$6:$B$600,D$6) -> 0 | E9: =SUMIFS('Emission per option-sector'!$D$6:$D$600,'Emission per option-sector'!$C$6:$C$600,'CO2 emissions per sector'!$A9,'Emission per option-sector'!$B$6:$B$600,E$6) -> 0 | H9: =-SUMIFS('Energy balance options'!$F$7:$F$4000,'Energy balance options'!$C$7:$C$4000,'CO2 emissions per sector'!$A9,'Energy balance options'!$B$7:$B$4000,"CO2flow") -> 0 | I9: =$I$4*H9/$H$28 -> 0 | K9: KIP built environment | L9: Huishoudens | M9: =B9-I9 -> 13.08703 | N9: =C9 -> 0 | O9: =D9 -> 0 | P9: =E9 -> 0 | R9: 13.533992
A10: HDO | B10: =SUMIFS('Emission per option-sector'!$D$6:$D$600,'Emission per option-sector'!$C$6:$C$600,'CO2 emissions per sector'!$A10,'Emission per option-sector'!$B$6:$B$600,B$6) -> 3.7198044 | C10: =SUMIFS('Emission per option-sector'!$D$6:$D$600,'Emission per option-sector'!$C$6:$C$600,'CO2 emissions per sector'!$A10,'Emission per option-sector'!$B$6:$B$600,C$6) -> 0 | D10: =SUMIFS('Emission per option-sector'!$D$6:$D$600,'Emission per option-sector'!$C$6:$C$600,'CO2 emissions per sector'!$A10,'Emission per option-sector'!$B$6:$B$600,D$6) -> 0 | E10: =SUMIFS('Emission per option-sector'!$D$6:$D$600,'Emission per option-sector'!$C$6:$C$600,'CO2 emissions per sector'!$A10,'Emission per option-sector'!$B$6:$B$600,E$6) -> 0 | H10: =-SUMIFS('Energy balance options'!$F$7:$F$4000,'Energy balance options'!$C$7:$C$4000,'CO2 emissions per sector'!$A10,'Energy balance options'!$B$7:$B$4000,"CO2flow") -> 0 | I10: =$I$4*H10/$H$28 -> 0 | K10: KIP built environment | L10: HDO | M10: =B10-I10 -> 3.7198044 | N10: =C10 -> 0 | O10: =D10 -> 0 | P10: =E10 -> 0 | R10: 4.4538084
A11: Bunkers | B11: =SUMIFS('Emission per option-sector'!$D$6:$D$600,'Emission per option-sector'!$C$6:$C$600,'CO2 emissions per sector'!$A11,'Emission per option-sector'!$B$6:$B$600,B$6) -> 0 | C11: =SUMIFS('Emission per option-sector'!$D$6:$D$600,'Emission per option-sector'!$C$6:$C$600,'CO2 emissions per sector'!$A11,'Emission per option-sector'!$B$6:$B$600,C$6) -> 9.9971522 | D11: =SUMIFS('Emission per option-sector'!$D$6:$D$600,'Emission per option-sector'!$C$6:$C$600,'CO2 emissions per sector'!$A11,'Emission per option-sector'!$B$6:$B$600,D$6) -> 32.547891 | E11: =SUMIFS('Emission per option-sector'!$D$6:$D$600,'Emission per option-sector'!$C$6:$C$600,'CO2 emissions per sector'!$A11,'Emission per option-sector'!$B$6:$B$600,E$6) -> 0 | H11: =-SUMIFS('Energy balance options'!$F$7:$F$4000,'Energy balance options'!$C$7:$C$4000,'CO2 emissions per sector'!$A11,'Energy balance options'!$B$7:$B$4000,"CO2flow") -> 0 | I11: =$I$4*H11/$H$28 -> 0 | K11: KIP bunkers | L11: Bunkers | M11: =B11-I11 -> 0 | N11: =C11 -> 9.9971522 | O11: =D11 -> 32.547891 | P11: =E11 -> 0 | S11: =14466.5918905326/1000 -> 14.466592 | T11: =36300.7824324009/1000 -> 36.300782
A12: Elektriciteitsopwekking | B12: =SUMIFS('Emission per option-sector'!$D$6:$D$600,'Emission per option-sector'!$C$6:$C$600,'CO2 emissions per sector'!$A12,'Emission per option-sector'!$B$6:$B$600,B$6) -> 5.4646982 | C12: =SUMIFS('Emission per option-sector'!$D$6:$D$600,'Emission per option-sector'!$C$6:$C$600,'CO2 emissions per sector'!$A12,'Emission per option-sector'!$B$6:$B$600,C$6) -> 0 | D12: =SUMIFS('Emission per option-sector'!$D$6:$D$600,'Emission per option-sector'!$C$6:$C$600,'CO2 emissions per sector'!$A12,'Emission per option-sector'!$B$6:$B$600,D$6) -> 0 | E12: =SUMIFS('Emission per option-sector'!$D$6:$D$600,'Emission per option-sector'!$C$6:$C$600,'CO2 emissions per sector'!$A12,'Emission per option-sector'!$B$6:$B$600,E$6) -> 0 | H12: =-SUMIFS('Energy balance options'!$F$7:$F$4000,'Energy balance options'!$C$7:$C$4000,'CO2 emissions per sector'!$A12,'Energy balance options'!$B$7:$B$4000,"CO2flow") -> 3.5081879e-05 | I12: =$I$4*H12/$H$28 -> 3.4653138e-05 | K12: KIP energy | L12: Elektriciteitsopwekking | M12: =B12-I12 -> 5.4646635 | N12: =C12 -> 0 | O12: =D12 -> 0 | P12: =E12 -> 0 | R12: 18.561762
A13: Warmteopwekking (centraal) | B13: =SUMIFS('Emission per option-sector'!$D$6:$D$600,'Emission per option-sector'!$C$6:$C$600,'CO2 emissions per sector'!$A13,'Emission per option-sector'!$B$6:$B$600,B$6) -> 1.0903514 | C13: =SUMIFS('Emission per option-sector'!$D$6:$D$600,'Emission per option-sector'!$C$6:$C$600,'CO2 emissions per sector'!$A13,'Emission per option-sector'!$B$6:$B$600,C$6) -> 0 | D13: =SUMIFS('Emission per option-sector'!$D$6:$D$600,'Emission per option-sector'!$C$6:$C$600,'CO2 emissions per sector'!$A13,'Emission per option-sector'!$B$6:$B$600,D$6) -> 0 | E13: =SUMIFS('Emission per option-sector'!$D$6:$D$600,'Emission per option-sector'!$C$6:$C$600,'CO2 emissions per sector'!$A13,'Emission per option-sector'!$B$6:$B$600,E$6) -> 0 | H13: =-SUMIFS('Energy balance options'!$F$7:$F$4000,'Energy balance options'!$C$7:$C$4000,'CO2 emissions per sector'!$A13,'Energy balance options'!$B$7:$B$4000,"CO2flow") -> 0 | I13: =$I$4*H13/$H$28 -> 0 | K13: KIP energy | L13: Warmteopwekking (centraal) | M13: =B13-I13 -> 1.0903514 | N13: =C13 -> 0 | O13: =D13 -> 0 | P13: =E13 -> 0 | R13: 0
A14: Basic metal non-ferro | B14: =SUMIFS('Emission per option-sector'!$D$6:$D$600,'Emission per option-sector'!$C$6:$C$600,'CO2 emissions per sector'!$A14,'Emission per option-sector'!$B$6:$B$600,B$6) -> 0.035650747 | C14: =SUMIFS('Emission per option-sector'!$D$6:$D$600,'Emission per option-sector'!$C$6:$C$600,'CO2 emissions per sector'!$A14,'Emission per option-sector'!$B$6:$B$600,C$6) -> 0 | D14: =SUMIFS('Emission per option-sector'!$D$6:$D$600,'Emission per option-sector'!$C$6:$C$600,'CO2 emissions per sector'!$A14,'Emission per option-sector'!$B$6:$B$600,D$6) -> 0 | E14: =SUMIFS('Emission per option-sector'!$D$6:$D$600,'Emission per option-sector'!$C$6:$C$600,'CO2 emissions per sector'!$A14,'Emission per option-sector'!$B$6:$B$600,E$6) -> 0 | H14: =-SUMIFS('Energy balance options'!$F$7:$F$4000,'Energy balance options'!$C$7:$C$4000,'CO2 emissions per sector'!$A14,'Energy balance options'!$B$7:$B$4000,"CO2flow") -> 0 | I14: =$I$4*H14/$H$28 -> 0 | K14: KIP industry | L14: Basic metal non-ferro | M14: =B14-I14 -> 0.035650747 | N14: =C14 -> 0 | O14: =D14 -> 0 | P14: =E14 -> 0 | R14: 0.18106797
A15: Basismetaal ferro | B15: =SUMIFS('Emission per option-sector'!$D$6:$D$600,'Emission per option-sector'!$C$6:$C$600,'CO2 emissions per sector'!$A15,'Emission per option-sector'!$B$6:$B$600,B$6) -> 5.07156 | C15: =SUMIFS('Emission per option-sector'!$D$6:$D$600,'Emission per option-sector'!$C$6:$C$600,'CO2 emissions per sector'!$A15,'Emission per option-sector'!$B$6:$B$600,C$6) -> 0 | D15: =SUMIFS('Emission per option-sector'!$D$6:$D$600,'Emission per option-sector'!$C$6:$C$600,'CO2 emissions per sector'!$A15,'Emission per option-sector'!$B$6:$B$600,D$6) -> 0 | E15: =SUMIFS('Emission per option-sector'!$D$6:$D$600,'Emission per option-sector'!$C$6:$C$600,'CO2 emissions per sector'!$A15,'Emission per option-sector'!$B$6:$B$600,E$6) -> 0 | H15: =-SUMIFS('Energy balance options'!$F$7:$F$4000,'Energy balance options'!$C$7:$C$4000,'CO2 emissions per sector'!$A15,'Energy balance options'!$B$7:$B$4000,"CO2flow") -> 1.3766777 | I15: =$I$4*H15/$H$28 -> 1.3598532 | K15: KIP industry | L15: Basismetaal ferro | M15: =B15-I15 -> 3.7117068 | N15: =C15 -> 0 | O15: =D15 -> 0 | P15: =E15 -> 0 | R15: 7.4996169
A16: Chemie | B16: =SUMIFS('Emission per option-sector'!$D$6:$D$600,'Emission per option-sector'!$C$6:$C$600,'CO2 emissions per sector'!$A16,'Emission per option-sector'!$B$6:$B$600,B$6) -> 12.723749 | C16: =SUMIFS('Emission per option-sector'!$D$6:$D$600,'Emission per option-sector'!$C$6:$C$600,'CO2 emissions per sector'!$A16,'Emission per option-sector'!$B$6:$B$600,C$6) -> 0 | D16: =SUMIFS('Emission per option-sector'!$D$6:$D$600,'Emission per option-sector'!$C$6:$C$600,'CO2 emissions per sector'!$A16,'Emission per option-sector'!$B$6:$B$600,D$6) -> 0 | E16: =SUMIFS('Emission per option-sector'!$D$6:$D$600,'Emission per option-sector'!$C$6:$C$600,'CO2 emissions per sector'!$A16,'Emission per option-sector'!$B$6:$B$600,E$6) -> 0 | H16: =-SUMIFS('Energy balance options'!$F$7:$F$4000,'Energy balance options'!$C$7:$C$4000,'CO2 emissions per sector'!$A16,'Energy balance options'!$B$7:$B$4000,"CO2flow") -> 5.6136744e-05 | I16: =$I$4*H16/$H$28 -> 5.5450689e-05 | K16: KIP industry | L16: Chemie | M16: =B16-I16 -> 12.723694 | N16: =C16 -> 0 | O16: =D16 -> 0 | P16: =E16 -> 0 | R16: =20.3380756129652+0.7416208-R21 -> 15.61621
A17: Food and Beverage Industry | B17: =SUMIFS('Emission per option-sector'!$D$6:$D$600,'Emission per option-sector'!$C$6:$C$600,'CO2 emissions per sector'!$A17,'Emission per option-sector'!$B$6:$B$600,B$6) -> 0.45064763 | C17: =SUMIFS('Emission per option-sector'!$D$6:$D$600,'Emission per option-sector'!$C$6:$C$600,'CO2 emissions per sector'!$A17,'Emission per option-sector'!$B$6:$B$600,C$6) -> 0 | D17: =SUMIFS('Emission per option-sector'!$D$6:$D$600,'Emission per option-sector'!$C$6:$C$600,'CO2 emissions per sector'!$A17,'Emission per option-sector'!$B$6:$B$600,D$6) -> 0 | E17: =SUMIFS('Emission per option-sector'!$D$6:$D$600,'Emission per option-sector'!$C$6:$C$600,'CO2 emissions per sector'!$A17,'Emission per option-sector'!$B$6:$B$600,E$6) -> 0 | H17: =-SUMIFS('Energy balance options'!$F$7:$F$4000,'Energy balance options'!$C$7:$C$4000,'CO2 emissions per sector'!$A17,'Energy balance options'!$B$7:$B$4000,"CO2flow") -> 0 | I17: =$I$4*H17/$H$28 -> 0 | K17: KIP industry | L17: Food and Beverage Industry | M17: =B17-I17 -> 0.45064763 | N17: =C17 -> 0 | O17: =D17 -> 0 | P17: =E17 -> 0 | R17: 3.2411075
